Workbook

Sheet How To

Sheet Reference Sheet

Sheet Overview (RESPONSES REQUIRED)
B1: MSR0983 - Band Combinations
B3: Note: band and feature enablement should refer to the latest version of MSR0295 pre-configuration requirements
B5: The green cells on this sheet, as well as any other relevant sheets through this workbook are to be completed/updated by the vendor
B7: Device Details | C7: Vendor Response
B8: Vendor name | C8: TCL
B9: Device Model | C9: Dahlia_T450H
B11: Feature Support
B12: Technology | C12: Vendor Response
B13: LTE CA | C13: Y
B14: EN-DC | C14: N
B15: EN-DC with NR CA | C15: N
B16: EN-DC with mmW | C16: N
B17: SA CA | C17: N
B18: SA CA with mmW | C18: N
B19: Power Class 2 on n1 | C19: N
B20: Power Class 2 on n3 | C20: N
B21: Power Class 2 on n7 | C21: N
B22: Power Class 2 on n78 | C22: N
B23: Power Class 2 on n78(2A) | C23: N
... B27: Power Class 1 on n78 | C27: N
B29: LTE Carrier Aggregation Band Combinations
B30: LTE CC | C30: Vendor Response
B31: Max LTE#CC | C31: 2
B32: LTE DL Cat | C32: 7
B33: LTE UL Cat | C33: 13
B34: Max LTE#SS | C34: =IFERROR(INDEX('CAT->streams LUT'!B1:B15,MATCH(C32,'CAT->streams LUT'!A1:A15)),0) -> 4
B36: LTE Uplink Support
B37: Uplink Combo | C37: Vendor Response | D37: Vendor Comments (Exception Cases eg Max carriers limit)
B38: CA_3C | C38: Y
B39: CA_7C | C39: N
B40: CA_1A-3A | C40: N
B41: CA_1A-7A | C41: N
B42: CA_1A-26A | C42: N
B43: CA_1A-28A | C43: N
B44: CA_3A-7A | C44: N
B45: CA_3A-26A | C45: N
B46: CA_3A-28A | C46: N
B47: CA_7A-26A | C47: N
B48: CA_7A-28A | C48: N
B50: EN-DC Band Combinations
...

Sheet CAT->streams LUT
A1: 4 | B1: 2
A2: 6 | B2: 4
A3: 7 | B3: 4
A4: 9 | B4: 6
A5: 10 | B5: 6
A6: 11 | B6: 6
A7: 12 | B7: 6
A8: 13 | B8: 4
A9: 15 | B9: 8
A10: 16 | B10: 10
A11: 18 | B11: 12
A12: 19 | B12: 16
... A15: 22 | B15: 24

Sheet LTE CA_BE
A1: User Equipment Requirement | B1: LTE#Bands | C1: LTE#CC | D1: LTE#SS | E1: Input | F1: 1A2 | G1: 1A4 | H1: 3A2 | I1: 3A4 | J1: 3C2 | K1: 3C4 | L1: 5A2 | M1: 7A2 | N1: 7A4 | O1: 7C2 | P1: 7C4 | Q1: 26A2 | R1: 26(2A)22 | S1: 28A2 | T1: True SUM | U1: Band# Comply | V1: Input Logic | W1: Band/Input Comply | X1: CC# Comply | Y1: SS# Comply | Z1: CC#/SS# Comply | AA1: Support
A3: CA_1A4-3C4-7C4-28A2 | B3: 4 | C3: 6 | D3: 22 | E3: =IF('LTE CA'!K5="Y", "Y", IF('LTE CA'!K5="N", "N", 0)) -> N | F3: =IFERROR(AND(OR(F1:G2,$V3)=TRUE,IF(SEARCH(F$1,$A3)>0,TRUE,FALSE)),"") | G3: =IFERROR(AND(OR(G1:G2,$V3)=TRUE,IF(SEARCH(G$1,$A3)>0,TRUE,FALSE)),"") -> FALSE | H3: =IFERROR(AND(OR(H1:K2,$V3)=TRUE,IF(SEARCH(H$1,$A3)>0,TRUE,FALSE)),"") | I3: =IFERROR(AND(OR(I1:K2,$V3)=TRUE,IF(SEARCH(I$1,$A3)>0,TRUE,FALSE)),"") | J3: =IFERROR(AND(OR(J1:K2,$V3)=TRUE,IF(SEARCH(J$1,$A3)>0,TRUE,FALSE)),"") | K3: =IFERROR(AND(OR(K1:K2,$V3)=TRUE,IF(SEARCH(K$1,$A3)>0,TRUE,FALSE)),"") -> FALSE | L3: =IFERROR(AND(OR(L1:L2,$V3)=TRUE,IF(SEARCH(L$1,$A3)>0,TRUE,FALSE)),"") | M3: =IFERROR(AND(OR(M1:P2,$V3)=TRUE,IF(SEARCH(M$1,$A3)>0,TRUE,FALSE)),"") | N3: =IFERROR(AND(OR(N1:P2,$V3)=TRUE,IF(SEARCH(N$1,$A3)>0,TRUE,FALSE)),"") | O3: =IFERROR(AND(OR(O1:P2,$V3)=TRUE,IF(SEARCH(O$1,$A3)>0,TRUE,FALSE)),"") | P3: =IFERROR(AND(OR(P1:P2,$V3)=TRUE,IF(SEARCH(P$1,$A3)>0,TRUE,FALSE)),"") -> FALSE | Q3: =IFERROR(AND(OR(Q1:R2,$V3)=TRUE,IF(SEARCH(Q$1,$A3)>0,TRUE,FALSE)),"") | R3: =IFERROR(AND(OR(R1:R2,$V3)=TRUE,IF(SEARCH(R$1,$A3)>0,TRUE,FALSE)),"") | S3: =IFERROR(AND(OR(S1:S2,$V3)=TRUE,IF(SEARCH(S$1,$A3)>0,TRUE,FALSE)),"") -> FALSE | T3: =COUNTIF(F3:S3,TRUE) -> 0 | U3: =IFERROR(AND(F3:S3), TRUE) -> FALSE | V3: =IF(E3="Y",TRUE,IF(E3="N",FALSE,0)) -> FALSE | W3: =IF(V3=FALSE, FALSE, U3) -> FALSE | X3: =IF(C3>'Overview (RESPONSES REQUIRED)'!$C$31,FALSE,TRUE) -> FALSE | Y3: =IF(D3>'Overview (RESPONSES REQUIRED)'!$C$34,FALSE,TRUE) -> FALSE | Z3: =AND(X3:Y3) -> FALSE | AA3: =IF(Z3=FALSE,"N",IF(W3=TRUE,"Y",IF(E3=0,"E","N"))) -> N
A4: CA_1A2-3C4-7C4-28A2 | B4: 4 | C4: 6 | D4: 20 | E4: =IF('LTE CA'!K6="Y", "Y", IF('LTE CA'!K6="N", "N", 0)) -> N | F4: =IFERROR(AND(OR(F1:G3,$V4)=TRUE,IF(SEARCH(F$1,$A4)>0,TRUE,FALSE)),"") -> FALSE | G4: =IFERROR(AND(OR(G1:G3,$V4)=TRUE,IF(SEARCH(G$1,$A4)>0,TRUE,FALSE)),"") | H4: =IFERROR(AND(OR(H1:K3,$V4)=TRUE,IF(SEARCH(H$1,$A4)>0,TRUE,FALSE)),"") | I4: =IFERROR(AND(OR(I1:K3,$V4)=TRUE,IF(SEARCH(I$1,$A4)>0,TRUE,FALSE)),"") | J4: =IFERROR(AND(OR(J1:K3,$V4)=TRUE,IF(SEARCH(J$1,$A4)>0,TRUE,FALSE)),"") | K4: =IFERROR(AND(OR(K1:K3,$V4)=TRUE,IF(SEARCH(K$1,$A4)>0,TRUE,FALSE)),"") -> FALSE | L4: =IFERROR(AND(OR(L1:L3,$V4)=TRUE,IF(SEARCH(L$1,$A4)>0,TRUE,FALSE)),"") | M4: =IFERROR(AND(OR(M1:P3,$V4)=TRUE,IF(SEARCH(M$1,$A4)>0,TRUE,FALSE)),"") | N4: =IFERROR(AND(OR(N1:P3,$V4)=TRUE,IF(SEARCH(N$1,$A4)>0,TRUE,FALSE)),"") | O4: =IFERROR(AND(OR(O1:P3,$V4)=TRUE,IF(SEARCH(O$1,$A4)>0,TRUE,FALSE)),"") | P4: =IFERROR(AND(OR(P1:P3,$V4)=TRUE,IF(SEARCH(P$1,$A4)>0,TRUE,FALSE)),"") -> FALSE | Q4: =IFERROR(AND(OR(Q1:R3,$V4)=TRUE,IF(SEARCH(Q$1,$A4)>0,TRUE,FALSE)),"") | R4: =IFERROR(AND(OR(R1:R3,$V4)=TRUE,IF(SEARCH(R$1,$A4)>0,TRUE,FALSE)),"") | S4: =IFERROR(AND(OR(S1:S3,$V4)=TRUE,IF(SEARCH(S$1,$A4)>0,TRUE,FALSE)),"") -> FALSE | T4: =COUNTIF(F4:S4,TRUE) -> 0 | U4: =IFERROR(AND(F4:S4), TRUE) -> FALSE | V4: =IF(E4="Y",TRUE,IF(E4="N",FALSE,0)) -> FALSE | W4: =IF(V4=FALSE, FALSE, U4) -> FALSE | X4: =IF(C4>'Overview (RESPONSES REQUIRED)'!$C$31,FALSE,TRUE) -> FALSE | Y4: =IF(D4>'Overview (RESPONSES REQUIRED)'!$C$34,FALSE,TRUE) -> FALSE | Z4: =AND(X4:Y4) -> FALSE | AA4: =IF(Z4=FALSE,"N",IF(W4=TRUE,"Y",IF(E4=0,"E","N"))) -> N
A5: CA_1A4-3C4-7C2-28A2 | B5: 4 | C5: 6 | D5: 18 | E5: =IF('LTE CA'!K7="Y", "Y", IF('LTE CA'!K7="N", "N", 0)) -> N | F5: =IFERROR(AND(OR(F1:G4,$V5)=TRUE,IF(SEARCH(F$1,$A5)>0,TRUE,FALSE)),"") | G5: =IFERROR(AND(OR(G1:G4,$V5)=TRUE,IF(SEARCH(G$1,$A5)>0,TRUE,FALSE)),"") -> FALSE | H5: =IFERROR(AND(OR(H1:K4,$V5)=TRUE,IF(SEARCH(H$1,$A5)>0,TRUE,FALSE)),"") | I5: =IFERROR(AND(OR(I1:K4,$V5)=TRUE,IF(SEARCH(I$1,$A5)>0,TRUE,FALSE)),"") | J5: =IFERROR(AND(OR(J1:K4,$V5)=TRUE,IF(SEARCH(J$1,$A5)>0,TRUE,FALSE)),"") | K5: =IFERROR(AND(OR(K1:K4,$V5)=TRUE,IF(SEARCH(K$1,$A5)>0,TRUE,FALSE)),"") -> FALSE | L5: =IFERROR(AND(OR(L1:L4,$V5)=TRUE,IF(SEARCH(L$1,$A5)>0,TRUE,FALSE)),"") | M5: =IFERROR(AND(OR(M1:P4,$V5)=TRUE,IF(SEARCH(M$1,$A5)>0,TRUE,FALSE)),"") | N5: =IFERROR(AND(OR(N1:P4,$V5)=TRUE,IF(SEARCH(N$1,$A5)>0,TRUE,FALSE)),"") | O5: =IFERROR(AND(OR(O1:P4,$V5)=TRUE,IF(SEARCH(O$1,$A5)>0,TRUE,FALSE)),"") -> FALSE | P5: =IFERROR(AND(OR(P1:P4,$V5)=TRUE,IF(SEARCH(P$1,$A5)>0,TRUE,FALSE)),"") | Q5: =IFERROR(AND(OR(Q1:R4,$V5)=TRUE,IF(SEARCH(Q$1,$A5)>0,TRUE,FALSE)),"") | R5: =IFERROR(AND(OR(R1:R4,$V5)=TRUE,IF(SEARCH(R$1,$A5)>0,TRUE,FALSE)),"") | S5: =IFERROR(AND(OR(S1:S4,$V5)=TRUE,IF(SEARCH(S$1,$A5)>0,TRUE,FALSE)),"") -> FALSE | T5: =COUNTIF(F5:S5,TRUE) -> 0 | U5: =IFERROR(AND(F5:S5), TRUE) -> FALSE | V5: =IF(E5="Y",TRUE,IF(E5="N",FALSE,0)) -> FALSE | W5: =IF(V5=FALSE, FALSE, U5) -> FALSE | X5: =IF(C5>'Overview (RESPONSES REQUIRED)'!$C$31,FALSE,TRUE) -> FALSE | Y5: =IF(D5>'Overview (RESPONSES REQUIRED)'!$C$34,FALSE,TRUE) -> FALSE | Z5: =AND(X5:Y5) -> FALSE | AA5: =IF(Z5=FALSE,"N",IF(W5=TRUE,"Y",IF(E5=0,"E","N"))) -> N
A6: CA_1A4-3C2-7C4-28A2 | B6: 4 | C6: 6 | D6: 18 | E6: =IF('LTE CA'!K8="Y", "Y", IF('LTE CA'!K8="N", "N", 0)) -> N | F6: =IFERROR(AND(OR(F1:G5,$V6)=TRUE,IF(SEARCH(F$1,$A6)>0,TRUE,FALSE)),"") | G6: =IFERROR(AND(OR(G1:G5,$V6)=TRUE,IF(SEARCH(G$1,$A6)>0,TRUE,FALSE)),"") -> FALSE | H6: =IFERROR(AND(OR(H1:K5,$V6)=TRUE,IF(SEARCH(H$1,$A6)>0,TRUE,FALSE)),"") | I6: =IFERROR(AND(OR(I1:K5,$V6)=TRUE,IF(SEARCH(I$1,$A6)>0,TRUE,FALSE)),"") | J6: =IFERROR(AND(OR(J1:K5,$V6)=TRUE,IF(SEARCH(J$1,$A6)>0,TRUE,FALSE)),"") -> FALSE | K6: =IFERROR(AND(OR(K1:K5,$V6)=TRUE,IF(SEARCH(K$1,$A6)>0,TRUE,FALSE)),"") | L6: =IFERROR(AND(OR(L1:L5,$V6)=TRUE,IF(SEARCH(L$1,$A6)>0,TRUE,FALSE)),"") | M6: =IFERROR(AND(OR(M1:P5,$V6)=TRUE,IF(SEARCH(M$1,$A6)>0,TRUE,FALSE)),"") | N6: =IFERROR(AND(OR(N1:P5,$V6)=TRUE,IF(SEARCH(N$1,$A6)>0,TRUE,FALSE)),"") | O6: =IFERROR(AND(OR(O1:P5,$V6)=TRUE,IF(SEARCH(O$1,$A6)>0,TRUE,FALSE)),"") | P6: =IFERROR(AND(OR(P1:P5,$V6)=TRUE,IF(SEARCH(P$1,$A6)>0,TRUE,FALSE)),"") -> FALSE | Q6: =IFERROR(AND(OR(Q1:R5,$V6)=TRUE,IF(SEARCH(Q$1,$A6)>0,TRUE,FALSE)),"") | R6: =IFERROR(AND(OR(R1:R5,$V6)=TRUE,IF(SEARCH(R$1,$A6)>0,TRUE,FALSE)),"") | S6: =IFERROR(AND(OR(S1:S5,$V6)=TRUE,IF(SEARCH(S$1,$A6)>0,TRUE,FALSE)),"") -> FALSE | T6: =COUNTIF(F6:S6,TRUE) -> 0 | U6: =IFERROR(AND(F6:S6), TRUE) -> FALSE | V6: =IF(E6="Y",TRUE,IF(E6="N",FALSE,0)) -> FALSE | W6: =IF(V6=FALSE, FALSE, U6) -> FALSE | X6: =IF(C6>'Overview (RESPONSES REQUIRED)'!$C$31,FALSE,TRUE) -> FALSE | Y6: =IF(D6>'Overview (RESPONSES REQUIRED)'!$C$34,FALSE,TRUE) -> FALSE | Z6: =AND(X6:Y6) -> FALSE | AA6: =IF(Z6=FALSE,"N",IF(W6=TRUE,"Y",IF(E6=0,"E","N"))) -> N
A7: CA_1A4-3A4-7C4-28A2 | B7: 4 | C7: 5 | D7: 18 | E7: =IF('LTE CA'!K9="Y", "Y", IF('LTE CA'!K9="N", "N", 0)) -> N | F7: =IFERROR(AND(OR(F1:G6,$V7)=TRUE,IF(SEARCH(F$1,$A7)>0,TRUE,FALSE)),"") | G7: =IFERROR(AND(OR(G1:G6,$V7)=TRUE,IF(SEARCH(G$1,$A7)>0,TRUE,FALSE)),"") -> FALSE | H7: =IFERROR(AND(OR(H1:K6,$V7)=TRUE,IF(SEARCH(H$1,$A7)>0,TRUE,FALSE)),"") | I7: =IFERROR(AND(OR(I1:K6,$V7)=TRUE,IF(SEARCH(I$1,$A7)>0,TRUE,FALSE)),"") -> FALSE | J7: =IFERROR(AND(OR(J1:K6,$V7)=TRUE,IF(SEARCH(J$1,$A7)>0,TRUE,FALSE)),"") | K7: =IFERROR(AND(OR(K1:K6,$V7)=TRUE,IF(SEARCH(K$1,$A7)>0,TRUE,FALSE)),"") | L7: =IFERROR(AND(OR(L1:L6,$V7)=TRUE,IF(SEARCH(L$1,$A7)>0,TRUE,FALSE)),"") | M7: =IFERROR(AND(OR(M1:P6,$V7)=TRUE,IF(SEARCH(M$1,$A7)>0,TRUE,FALSE)),"") | N7: =IFERROR(AND(OR(N1:P6,$V7)=TRUE,IF(SEARCH(N$1,$A7)>0,TRUE,FALSE)),"") | O7: =IFERROR(AND(OR(O1:P6,$V7)=TRUE,IF(SEARCH(O$1,$A7)>0,TRUE,FALSE)),"") | P7: =IFERROR(AND(OR(P1:P6,$V7)=TRUE,IF(SEARCH(P$1,$A7)>0,TRUE,FALSE)),"") -> FALSE | Q7: =IFERROR(AND(OR(Q1:R6,$V7)=TRUE,IF(SEARCH(Q$1,$A7)>0,TRUE,FALSE)),"") | R7: =IFERROR(AND(OR(R1:R6,$V7)=TRUE,IF(SEARCH(R$1,$A7)>0,TRUE,FALSE)),"") | S7: =IFERROR(AND(OR(S1:S6,$V7)=TRUE,IF(SEARCH(S$1,$A7)>0,TRUE,FALSE)),"") -> FALSE | T7: =COUNTIF(F7:S7,TRUE) -> 0 | U7: =IFERROR(AND(F7:S7), TRUE) -> FALSE | V7: =IF(E7="Y",TRUE,IF(E7="N",FALSE,0)) -> FALSE | W7: =IF(V7=FALSE, FALSE, U7) -> FALSE | X7: =IF(C7>'Overview (RESPONSES REQUIRED)'!$C$31,FALSE,TRUE) -> FALSE | Y7: =IF(D7>'Overview (RESPONSES REQUIRED)'!$C$34,FALSE,TRUE) -> FALSE | Z7: =AND(X7:Y7) -> FALSE | AA7: =IF(Z7=FALSE,"N",IF(W7=TRUE,"Y",IF(E7=0,"E","N"))) -> N
A8: CA_1A4-3C4-7A4-28A2 | B8: 4 | C8: 5 | D8: 18 | E8: =IF('LTE CA'!K10="Y", "Y", IF('LTE CA'!K10="N", "N", 0)) -> N | F8: =IFERROR(AND(OR(F1:G7,$V8)=TRUE,IF(SEARCH(F$1,$A8)>0,TRUE,FALSE)),"") | G8: =IFERROR(AND(OR(G1:G7,$V8)=TRUE,IF(SEARCH(G$1,$A8)>0,TRUE,FALSE)),"") -> FALSE | H8: =IFERROR(AND(OR(H1:K7,$V8)=TRUE,IF(SEARCH(H$1,$A8)>0,TRUE,FALSE)),"") | I8: =IFERROR(AND(OR(I1:K7,$V8)=TRUE,IF(SEARCH(I$1,$A8)>0,TRUE,FALSE)),"") | J8: =IFERROR(AND(OR(J1:K7,$V8)=TRUE,IF(SEARCH(J$1,$A8)>0,TRUE,FALSE)),"") | K8: =IFERROR(AND(OR(K1:K7,$V8)=TRUE,IF(SEARCH(K$1,$A8)>0,TRUE,FALSE)),"") -> FALSE | L8: =IFERROR(AND(OR(L1:L7,$V8)=TRUE,IF(SEARCH(L$1,$A8)>0,TRUE,FALSE)),"") | M8: =IFERROR(AND(OR(M1:P7,$V8)=TRUE,IF(SEARCH(M$1,$A8)>0,TRUE,FALSE)),"") | N8: =IFERROR(AND(OR(N1:P7,$V8)=TRUE,IF(SEARCH(N$1,$A8)>0,TRUE,FALSE)),"") -> FALSE | O8: =IFERROR(AND(OR(O1:P7,$V8)=TRUE,IF(SEARCH(O$1,$A8)>0,TRUE,FALSE)),"") | P8: =IFERROR(AND(OR(P1:P7,$V8)=TRUE,IF(SEARCH(P$1,$A8)>0,TRUE,FALSE)),"") | Q8: =IFERROR(AND(OR(Q1:R7,$V8)=TRUE,IF(SEARCH(Q$1,$A8)>0,TRUE,FALSE)),"") | R8: =IFERROR(AND(OR(R1:R7,$V8)=TRUE,IF(SEARCH(R$1,$A8)>0,TRUE,FALSE)),"") | S8: =IFERROR(AND(OR(S1:S7,$V8)=TRUE,IF(SEARCH(S$1,$A8)>0,TRUE,FALSE)),"") -> FALSE | T8: =COUNTIF(F8:S8,TRUE) -> 0 | U8: =IFERROR(AND(F8:S8), TRUE) -> FALSE | V8: =IF(E8="Y",TRUE,IF(E8="N",FALSE,0)) -> FALSE | W8: =IF(V8=FALSE, FALSE, U8) -> FALSE | X8: =IF(C8>'Overview (RESPONSES REQUIRED)'!$C$31,FALSE,TRUE) -> FALSE | Y8: =IF(D8>'Overview (RESPONSES REQUIRED)'!$C$34,FALSE,TRUE) -> FALSE | Z8: =AND(X8:Y8) -> FALSE | AA8: =IF(Z8=FALSE,"N",IF(W8=TRUE,"Y",IF(E8=0,"E","N"))) -> N
A9: CA_1A2-3C2-7C4-28A2 | B9: 4 | C9: 6 | D9: 16 | E9: =IF('LTE CA'!K11="Y", "Y", IF('LTE CA'!K11="N", "N", 0)) -> N | F9: =IFERROR(AND(OR(F1:G8,$V9)=TRUE,IF(SEARCH(F$1,$A9)>0,TRUE,FALSE)),"") -> FALSE | G9: =IFERROR(AND(OR(G1:G8,$V9)=TRUE,IF(SEARCH(G$1,$A9)>0,TRUE,FALSE)),"") | H9: =IFERROR(AND(OR(H1:K8,$V9)=TRUE,IF(SEARCH(H$1,$A9)>0,TRUE,FALSE)),"") | I9: =IFERROR(AND(OR(I1:K8,$V9)=TRUE,IF(SEARCH(I$1,$A9)>0,TRUE,FALSE)),"") | J9: =IFERROR(AND(OR(J1:K8,$V9)=TRUE,IF(SEARCH(J$1,$A9)>0,TRUE,FALSE)),"") -> FALSE | K9: =IFERROR(AND(OR(K1:K8,$V9)=TRUE,IF(SEARCH(K$1,$A9)>0,TRUE,FALSE)),"") | L9: =IFERROR(AND(OR(L1:L8,$V9)=TRUE,IF(SEARCH(L$1,$A9)>0,TRUE,FALSE)),"") | M9: =IFERROR(AND(OR(M1:P8,$V9)=TRUE,IF(SEARCH(M$1,$A9)>0,TRUE,FALSE)),"") | N9: =IFERROR(AND(OR(N1:P8,$V9)=TRUE,IF(SEARCH(N$1,$A9)>0,TRUE,FALSE)),"") | O9: =IFERROR(AND(OR(O1:P8,$V9)=TRUE,IF(SEARCH(O$1,$A9)>0,TRUE,FALSE)),"") | P9: =IFERROR(AND(OR(P1:P8,$V9)=TRUE,IF(SEARCH(P$1,$A9)>0,TRUE,FALSE)),"") -> FALSE | Q9: =IFERROR(AND(OR(Q1:R8,$V9)=TRUE,IF(SEARCH(Q$1,$A9)>0,TRUE,FALSE)),"") | R9: =IFERROR(AND(OR(R1:R8,$V9)=TRUE,IF(SEARCH(R$1,$A9)>0,TRUE,FALSE)),"") | S9: =IFERROR(AND(OR(S1:S8,$V9)=TRUE,IF(SEARCH(S$1,$A9)>0,TRUE,FALSE)),"") -> FALSE | T9: =COUNTIF(F9:S9,TRUE) -> 0 | U9: =IFERROR(AND(F9:S9), TRUE) -> FALSE | V9: =IF(E9="Y",TRUE,IF(E9="N",FALSE,0)) -> FALSE | W9: =IF(V9=FALSE, FALSE, U9) -> FALSE | X9: =IF(C9>'Overview (RESPONSES REQUIRED)'!$C$31,FALSE,TRUE) -> FALSE | Y9: =IF(D9>'Overview (RESPONSES REQUIRED)'!$C$34,FALSE,TRUE) -> FALSE | Z9: =AND(X9:Y9) -> FALSE | AA9: =IF(Z9=FALSE,"N",IF(W9=TRUE,"Y",IF(E9=0,"E","N"))) -> N
A10: CA_1A2-3C4-7C2-28A2 | B10: 4 | C10: 6 | D10: 16 | E10: =IF('LTE CA'!K12="Y", "Y", IF('LTE CA'!K12="N", "N", 0)) -> N | F10: =IFERROR(AND(OR(F1:G9,$V10)=TRUE,IF(SEARCH(F$1,$A10)>0,TRUE,FALSE)),"") -> FALSE | G10: =IFERROR(AND(OR(G1:G9,$V10)=TRUE,IF(SEARCH(G$1,$A10)>0,TRUE,FALSE)),"") | H10: =IFERROR(AND(OR(H1:K9,$V10)=TRUE,IF(SEARCH(H$1,$A10)>0,TRUE,FALSE)),"") | I10: =IFERROR(AND(OR(I1:K9,$V10)=TRUE,IF(SEARCH(I$1,$A10)>0,TRUE,FALSE)),"") | J10: =IFERROR(AND(OR(J1:K9,$V10)=TRUE,IF(SEARCH(J$1,$A10)>0,TRUE,FALSE)),"") | K10: =IFERROR(AND(OR(K1:K9,$V10)=TRUE,IF(SEARCH(K$1,$A10)>0,TRUE,FALSE)),"") -> FALSE | L10: =IFERROR(AND(OR(L1:L9,$V10)=TRUE,IF(SEARCH(L$1,$A10)>0,TRUE,FALSE)),"") | M10: =IFERROR(AND(OR(M1:P9,$V10)=TRUE,IF(SEARCH(M$1,$A10)>0,TRUE,FALSE)),"") | N10: =IFERROR(AND(OR(N1:P9,$V10)=TRUE,IF(SEARCH(N$1,$A10)>0,TRUE,FALSE)),"") | O10: =IFERROR(AND(OR(O1:P9,$V10)=TRUE,IF(SEARCH(O$1,$A10)>0,TRUE,FALSE)),"") -> FALSE | P10: =IFERROR(AND(OR(P1:P9,$V10)=TRUE,IF(SEARCH(P$1,$A10)>0,TRUE,FALSE)),"") | Q10: =IFERROR(AND(OR(Q1:R9,$V10)=TRUE,IF(SEARCH(Q$1,$A10)>0,TRUE,FALSE)),"") | R10: =IFERROR(AND(OR(R1:R9,$V10)=TRUE,IF(SEARCH(R$1,$A10)>0,TRUE,FALSE)),"") | S10: =IFERROR(AND(OR(S1:S9,$V10)=TRUE,IF(SEARCH(S$1,$A10)>0,TRUE,FALSE)),"") -> FALSE | T10: =COUNTIF(F10:S10,TRUE) -> 0 | U10: =IFERROR(AND(F10:S10), TRUE) -> FALSE | V10: =IF(E10="Y",TRUE,IF(E10="N",FALSE,0)) -> FALSE | W10: =IF(V10=FALSE, FALSE, U10) -> FALSE | X10: =IF(C10>'Overview (RESPONSES REQUIRED)'!$C$31,FALSE,TRUE) -> FALSE | Y10: =IF(D10>'Overview (RESPONSES REQUIRED)'!$C$34,FALSE,TRUE) -> FALSE | Z10: =AND(X10:Y10) -> FALSE | AA10: =IF(Z10=FALSE,"N",IF(W10=TRUE,"Y",IF(E10=0,"E","N"))) -> N
A11: CA_1A2-3A4-7C4-28A2 | B11: 4 | C11: 5 | D11: 16 | E11: =IF('LTE CA'!K13="Y", "Y", IF('LTE CA'!K13="N", "N", 0)) -> N | F11: =IFERROR(AND(OR(F1:G10,$V11)=TRUE,IF(SEARCH(F$1,$A11)>0,TRUE,FALSE)),"") -> FALSE | G11: =IFERROR(AND(OR(G1:G10,$V11)=TRUE,IF(SEARCH(G$1,$A11)>0,TRUE,FALSE)),"") | H11: =IFERROR(AND(OR(H1:K10,$V11)=TRUE,IF(SEARCH(H$1,$A11)>0,TRUE,FALSE)),"") | I11: =IFERROR(AND(OR(I1:K10,$V11)=TRUE,IF(SEARCH(I$1,$A11)>0,TRUE,FALSE)),"") -> FALSE | J11: =IFERROR(AND(OR(J1:K10,$V11)=TRUE,IF(SEARCH(J$1,$A11)>0,TRUE,FALSE)),"") | K11: =IFERROR(AND(OR(K1:K10,$V11)=TRUE,IF(SEARCH(K$1,$A11)>0,TRUE,FALSE)),"") | L11: =IFERROR(AND(OR(L1:L10,$V11)=TRUE,IF(SEARCH(L$1,$A11)>0,TRUE,FALSE)),"") | M11: =IFERROR(AND(OR(M1:P10,$V11)=TRUE,IF(SEARCH(M$1,$A11)>0,TRUE,FALSE)),"") | N11: =IFERROR(AND(OR(N1:P10,$V11)=TRUE,IF(SEARCH(N$1,$A11)>0,TRUE,FALSE)),"") | O11: =IFERROR(AND(OR(O1:P10,$V11)=TRUE,IF(SEARCH(O$1,$A11)>0,TRUE,FALSE)),"") | P11: =IFERROR(AND(OR(P1:P10,$V11)=TRUE,IF(SEARCH(P$1,$A11)>0,TRUE,FALSE)),"") -> FALSE | Q11: =IFERROR(AND(OR(Q1:R10,$V11)=TRUE,IF(SEARCH(Q$1,$A11)>0,TRUE,FALSE)),"") | R11: =IFERROR(AND(OR(R1:R10,$V11)=TRUE,IF(SEARCH(R$1,$A11)>0,TRUE,FALSE)),"") | S11: =IFERROR(AND(OR(S1:S10,$V11)=TRUE,IF(SEARCH(S$1,$A11)>0,TRUE,FALSE)),"") -> FALSE | T11: =COUNTIF(F11:S11,TRUE) -> 0 | U11: =IFERROR(AND(F11:S11), TRUE) -> FALSE | V11: =IF(E11="Y",TRUE,IF(E11="N",FALSE,0)) -> FALSE | W11: =IF(V11=FALSE, FALSE, U11) -> FALSE | X11: =IF(C11>'Overview (RESPONSES REQUIRED)'!$C$31,FALSE,TRUE) -> FALSE | Y11: =IF(D11>'Overview (RESPONSES REQUIRED)'!$C$34,FALSE,TRUE) -> FALSE | Z11: =AND(X11:Y11) -> FALSE | AA11: =IF(Z11=FALSE,"N",IF(W11=TRUE,"Y",IF(E11=0,"E","N"))) -> N
A12: CA_1A2-3C4-7A4-28A2 | B12: 4 | C12: 5 | D12: 16 | E12: =IF('LTE CA'!K14="Y", "Y", IF('LTE CA'!K14="N", "N", 0)) -> N | F12: =IFERROR(AND(OR(F1:G11,$V12)=TRUE,IF(SEARCH(F$1,$A12)>0,TRUE,FALSE)),"") -> FALSE | G12: =IFERROR(AND(OR(G1:G11,$V12)=TRUE,IF(SEARCH(G$1,$A12)>0,TRUE,FALSE)),"") | H12: =IFERROR(AND(OR(H1:K11,$V12)=TRUE,IF(SEARCH(H$1,$A12)>0,TRUE,FALSE)),"") | I12: =IFERROR(AND(OR(I1:K11,$V12)=TRUE,IF(SEARCH(I$1,$A12)>0,TRUE,FALSE)),"") | J12: =IFERROR(AND(OR(J1:K11,$V12)=TRUE,IF(SEARCH(J$1,$A12)>0,TRUE,FALSE)),"") | K12: =IFERROR(AND(OR(K1:K11,$V12)=TRUE,IF(SEARCH(K$1,$A12)>0,TRUE,FALSE)),"") -> FALSE | L12: =IFERROR(AND(OR(L1:L11,$V12)=TRUE,IF(SEARCH(L$1,$A12)>0,TRUE,FALSE)),"") | M12: =IFERROR(AND(OR(M1:P11,$V12)=TRUE,IF(SEARCH(M$1,$A12)>0,TRUE,FALSE)),"") | N12: =IFERROR(AND(OR(N1:P11,$V12)=TRUE,IF(SEARCH(N$1,$A12)>0,TRUE,FALSE)),"") -> FALSE | O12: =IFERROR(AND(OR(O1:P11,$V12)=TRUE,IF(SEARCH(O$1,$A12)>0,TRUE,FALSE)),"") | P12: =IFERROR(AND(OR(P1:P11,$V12)=TRUE,IF(SEARCH(P$1,$A12)>0,TRUE,FALSE)),"") | Q12: =IFERROR(AND(OR(Q1:R11,$V12)=TRUE,IF(SEARCH(Q$1,$A12)>0,TRUE,FALSE)),"") | R12: =IFERROR(AND(OR(R1:R11,$V12)=TRUE,IF(SEARCH(R$1,$A12)>0,TRUE,FALSE)),"") | S12: =IFERROR(AND(OR(S1:S11,$V12)=TRUE,IF(SEARCH(S$1,$A12)>0,TRUE,FALSE)),"") -> FALSE | T12: =COUNTIF(F12:S12,TRUE) -> 0 | U12: =IFERROR(AND(F12:S12), TRUE) -> FALSE | V12: =IF(E12="Y",TRUE,IF(E12="N",FALSE,0)) -> FALSE | W12: =IF(V12=FALSE, FALSE, U12) -> FALSE | X12: =IF(C12>'Overview (RESPONSES REQUIRED)'!$C$31,FALSE,TRUE) -> FALSE | Y12: =IF(D12>'Overview (RESPONSES REQUIRED)'!$C$34,FALSE,TRUE) -> FALSE | Z12: =AND(X12:Y12) -> FALSE | AA12: =IF(Z12=FALSE,"N",IF(W12=TRUE,"Y",IF(E12=0,"E","N"))) -> N
A13: CA_1A4-3C2-7C2-28A2 | B13: 4 | C13: 6 | D13: 14 | E13: =IF('LTE CA'!K15="Y", "Y", IF('LTE CA'!K15="N", "N", 0)) -> N | F13: =IFERROR(AND(OR(F1:G12,$V13)=TRUE,IF(SEARCH(F$1,$A13)>0,TRUE,FALSE)),"") | G13: =IFERROR(AND(OR(G1:G12,$V13)=TRUE,IF(SEARCH(G$1,$A13)>0,TRUE,FALSE)),"") -> FALSE | H13: =IFERROR(AND(OR(H1:K12,$V13)=TRUE,IF(SEARCH(H$1,$A13)>0,TRUE,FALSE)),"") | I13: =IFERROR(AND(OR(I1:K12,$V13)=TRUE,IF(SEARCH(I$1,$A13)>0,TRUE,FALSE)),"") | J13: =IFERROR(AND(OR(J1:K12,$V13)=TRUE,IF(SEARCH(J$1,$A13)>0,TRUE,FALSE)),"") -> FALSE | K13: =IFERROR(AND(OR(K1:K12,$V13)=TRUE,IF(SEARCH(K$1,$A13)>0,TRUE,FALSE)),"") | L13: =IFERROR(AND(OR(L1:L12,$V13)=TRUE,IF(SEARCH(L$1,$A13)>0,TRUE,FALSE)),"") | M13: =IFERROR(AND(OR(M1:P12,$V13)=TRUE,IF(SEARCH(M$1,$A13)>0,TRUE,FALSE)),"") | N13: =IFERROR(AND(OR(N1:P12,$V13)=TRUE,IF(SEARCH(N$1,$A13)>0,TRUE,FALSE)),"") | O13: =IFERROR(AND(OR(O1:P12,$V13)=TRUE,IF(SEARCH(O$1,$A13)>0,TRUE,FALSE)),"") -> FALSE | P13: =IFERROR(AND(OR(P1:P12,$V13)=TRUE,IF(SEARCH(P$1,$A13)>0,TRUE,FALSE)),"") | Q13: =IFERROR(AND(OR(Q1:R12,$V13)=TRUE,IF(SEARCH(Q$1,$A13)>0,TRUE,FALSE)),"") | R13: =IFERROR(AND(OR(R1:R12,$V13)=TRUE,IF(SEARCH(R$1,$A13)>0,TRUE,FALSE)),"") | S13: =IFERROR(AND(OR(S1:S12,$V13)=TRUE,IF(SEARCH(S$1,$A13)>0,TRUE,FALSE)),"") -> FALSE | T13: =COUNTIF(F13:S13,TRUE) -> 0 | U13: =IFERROR(AND(F13:S13), TRUE) -> FALSE | V13: =IF(E13="Y",TRUE,IF(E13="N",FALSE,0)) -> FALSE | W13: =IF(V13=FALSE, FALSE, U13) -> FALSE | X13: =IF(C13>'Overview (RESPONSES REQUIRED)'!$C$31,FALSE,TRUE) -> FALSE | Y13: =IF(D13>'Overview (RESPONSES REQUIRED)'!$C$34,FALSE,TRUE) -> FALSE | Z13: =AND(X13:Y13) -> FALSE | AA13: =IF(Z13=FALSE,"N",IF(W13=TRUE,"Y",IF(E13=0,"E","N"))) -> N
A14: CA_1A2-3A2-7C4-28A2 | B14: 4 | C14: 5 | D14: 14 | E14: =IF('LTE CA'!K16="Y", "Y", IF('LTE CA'!K16="N", "N", 0)) -> N | F14: =IFERROR(AND(OR(F1:G13,$V14)=TRUE,IF(SEARCH(F$1,$A14)>0,TRUE,FALSE)),"") -> FALSE | G14: =IFERROR(AND(OR(G1:G13,$V14)=TRUE,IF(SEARCH(G$1,$A14)>0,TRUE,FALSE)),"") | H14: =IFERROR(AND(OR(H1:K13,$V14)=TRUE,IF(SEARCH(H$1,$A14)>0,TRUE,FALSE)),"") -> FALSE | I14: =IFERROR(AND(OR(I1:K13,$V14)=TRUE,IF(SEARCH(I$1,$A14)>0,TRUE,FALSE)),"") | J14: =IFERROR(AND(OR(J1:K13,$V14)=TRUE,IF(SEARCH(J$1,$A14)>0,TRUE,FALSE)),"") | K14: =IFERROR(AND(OR(K1:K13,$V14)=TRUE,IF(SEARCH(K$1,$A14)>0,TRUE,FALSE)),"") | L14: =IFERROR(AND(OR(L1:L13,$V14)=TRUE,IF(SEARCH(L$1,$A14)>0,TRUE,FALSE)),"") | M14: =IFERROR(AND(OR(M1:P13,$V14)=TRUE,IF(SEARCH(M$1,$A14)>0,TRUE,FALSE)),"") | N14: =IFERROR(AND(OR(N1:P13,$V14)=TRUE,IF(SEARCH(N$1,$A14)>0,TRUE,FALSE)),"") | O14: =IFERROR(AND(OR(O1:P13,$V14)=TRUE,IF(SEARCH(O$1,$A14)>0,TRUE,FALSE)),"") | P14: =IFERROR(AND(OR(P1:P13,$V14)=TRUE,IF(SEARCH(P$1,$A14)>0,TRUE,FALSE)),"") -> FALSE | Q14: =IFERROR(AND(OR(Q1:R13,$V14)=TRUE,IF(SEARCH(Q$1,$A14)>0,TRUE,FALSE)),"") | R14: =IFERROR(AND(OR(R1:R13,$V14)=TRUE,IF(SEARCH(R$1,$A14)>0,TRUE,FALSE)),"") | S14: =IFERROR(AND(OR(S1:S13,$V14)=TRUE,IF(SEARCH(S$1,$A14)>0,TRUE,FALSE)),"") -> FALSE | T14: =COUNTIF(F14:S14,TRUE) -> 0 | U14: =IFERROR(AND(F14:S14), TRUE) -> FALSE | V14: =IF(E14="Y",TRUE,IF(E14="N",FALSE,0)) -> FALSE | W14: =IF(V14=FALSE, FALSE, U14) -> FALSE | X14: =IF(C14>'Overview (RESPONSES REQUIRED)'!$C$31,FALSE,TRUE) -> FALSE | Y14: =IF(D14>'Overview (RESPONSES REQUIRED)'!$C$34,FALSE,TRUE) -> FALSE | Z14: =AND(X14:Y14) -> FALSE | AA14: =IF(Z14=FALSE,"N",IF(W14=TRUE,"Y",IF(E14=0,"E","N"))) -> N
A15: CA_1A2-3C4-7A2-28A2 | B15: 4 | C15: 5 | D15: 14 | E15: =IF('LTE CA'!K17="Y", "Y", IF('LTE CA'!K17="N", "N", 0)) -> N | F15: =IFERROR(AND(OR(F1:G14,$V15)=TRUE,IF(SEARCH(F$1,$A15)>0,TRUE,FALSE)),"") -> FALSE | G15: =IFERROR(AND(OR(G1:G14,$V15)=TRUE,IF(SEARCH(G$1,$A15)>0,TRUE,FALSE)),"") | H15: =IFERROR(AND(OR(H1:K14,$V15)=TRUE,IF(SEARCH(H$1,$A15)>0,TRUE,FALSE)),"") | I15: =IFERROR(AND(OR(I1:K14,$V15)=TRUE,IF(SEARCH(I$1,$A15)>0,TRUE,FALSE)),"") | J15: =IFERROR(AND(OR(J1:K14,$V15)=TRUE,IF(SEARCH(J$1,$A15)>0,TRUE,FALSE)),"") | K15: =IFERROR(AND(OR(K1:K14,$V15)=TRUE,IF(SEARCH(K$1,$A15)>0,TRUE,FALSE)),"") -> FALSE | L15: =IFERROR(AND(OR(L1:L14,$V15)=TRUE,IF(SEARCH(L$1,$A15)>0,TRUE,FALSE)),"") | M15: =IFERROR(AND(OR(M1:P14,$V15)=TRUE,IF(SEARCH(M$1,$A15)>0,TRUE,FALSE)),"") -> FALSE | N15: =IFERROR(AND(OR(N1:P14,$V15)=TRUE,IF(SEARCH(N$1,$A15)>0,TRUE,FALSE)),"") | O15: =IFERROR(AND(OR(O1:P14,$V15)=TRUE,IF(SEARCH(O$1,$A15)>0,TRUE,FALSE)),"") | P15: =IFERROR(AND(OR(P1:P14,$V15)=TRUE,IF(SEARCH(P$1,$A15)>0,TRUE,FALSE)),"") | Q15: =IFERROR(AND(OR(Q1:R14,$V15)=TRUE,IF(SEARCH(Q$1,$A15)>0,TRUE,FALSE)),"") | R15: =IFERROR(AND(OR(R1:R14,$V15)=TRUE,IF(SEARCH(R$1,$A15)>0,TRUE,FALSE)),"") | S15: =IFERROR(AND(OR(S1:S14,$V15)=TRUE,IF(SEARCH(S$1,$A15)>0,TRUE,FALSE)),"") -> FALSE | T15: =COUNTIF(F15:S15,TRUE) -> 0 | U15: =IFERROR(AND(F15:S15), TRUE) -> FALSE | V15: =IF(E15="Y",TRUE,IF(E15="N",FALSE,0)) -> FALSE | W15: =IF(V15=FALSE, FALSE, U15) -> FALSE | X15: =IF(C15>'Overview (RESPONSES REQUIRED)'!$C$31,FALSE,TRUE) -> FALSE | Y15: =IF(D15>'Overview (RESPONSES REQUIRED)'!$C$34,FALSE,TRUE) -> FALSE | Z15: =AND(X15:Y15) -> FALSE | AA15: =IF(Z15=FALSE,"N",IF(W15=TRUE,"Y",IF(E15=0,"E","N"))) -> N
A16: CA_1A4-3A4-7A4-28A2 | B16: 4 | C16: 4 | D16: 14 | E16: =IF('LTE CA'!K18="Y", "Y", IF('LTE CA'!K18="N", "N", 0)) -> N | F16: =IFERROR(AND(OR(F1:G15,$V16)=TRUE,IF(SEARCH(F$1,$A16)>0,TRUE,FALSE)),"") | G16: =IFERROR(AND(OR(G1:G15,$V16)=TRUE,IF(SEARCH(G$1,$A16)>0,TRUE,FALSE)),"") -> FALSE | H16: =IFERROR(AND(OR(H1:K15,$V16)=TRUE,IF(SEARCH(H$1,$A16)>0,TRUE,FALSE)),"") | I16: =IFERROR(AND(OR(I1:K15,$V16)=TRUE,IF(SEARCH(I$1,$A16)>0,TRUE,FALSE)),"") -> FALSE | J16: =IFERROR(AND(OR(J1:K15,$V16)=TRUE,IF(SEARCH(J$1,$A16)>0,TRUE,FALSE)),"") | K16: =IFERROR(AND(OR(K1:K15,$V16)=TRUE,IF(SEARCH(K$1,$A16)>0,TRUE,FALSE)),"") | L16: =IFERROR(AND(OR(L1:L15,$V16)=TRUE,IF(SEARCH(L$1,$A16)>0,TRUE,FALSE)),"") | M16: =IFERROR(AND(OR(M1:P15,$V16)=TRUE,IF(SEARCH(M$1,$A16)>0,TRUE,FALSE)),"") | N16: =IFERROR(AND(OR(N1:P15,$V16)=TRUE,IF(SEARCH(N$1,$A16)>0,TRUE,FALSE)),"") -> FALSE | O16: =IFERROR(AND(OR(O1:P15,$V16)=TRUE,IF(SEARCH(O$1,$A16)>0,TRUE,FALSE)),"") | P16: =IFERROR(AND(OR(P1:P15,$V16)=TRUE,IF(SEARCH(P$1,$A16)>0,TRUE,FALSE)),"") | Q16: =IFERROR(AND(OR(Q1:R15,$V16)=TRUE,IF(SEARCH(Q$1,$A16)>0,TRUE,FALSE)),"") | R16: =IFERROR(AND(OR(R1:R15,$V16)=TRUE,IF(SEARCH(R$1,$A16)>0,TRUE,FALSE)),"") | S16: =IFERROR(AND(OR(S1:S15,$V16)=TRUE,IF(SEARCH(S$1,$A16)>0,TRUE,FALSE)),"") -> FALSE | T16: =COUNTIF(F16:S16,TRUE) -> 0 | U16: =IFERROR(AND(F16:S16), TRUE) -> FALSE | V16: =IF(E16="Y",TRUE,IF(E16="N",FALSE,0)) -> FALSE | W16: =IF(V16=FALSE, FALSE, U16) -> FALSE | X16: =IF(C16>'Overview (RESPONSES REQUIRED)'!$C$31,FALSE,TRUE) -> FALSE | Y16: =IF(D16>'Overview (RESPONSES REQUIRED)'!$C$34,FALSE,TRUE) -> FALSE | Z16: =AND(X16:Y16) -> FALSE | AA16: =IF(Z16=FALSE,"N",IF(W16=TRUE,"Y",IF(E16=0,"E","N"))) -> N
A17: CA_1A2-3C2-7C2-28A2 | B17: 4 | C17: 6 | D17: 12 | E17: =IF('LTE CA'!K19="Y", "Y", IF('LTE CA'!K19="N", "N", 0)) -> N | F17: =IFERROR(AND(OR(F1:G16,$V17)=TRUE,IF(SEARCH(F$1,$A17)>0,TRUE,FALSE)),"") -> FALSE | G17: =IFERROR(AND(OR(G1:G16,$V17)=TRUE,IF(SEARCH(G$1,$A17)>0,TRUE,FALSE)),"") | H17: =IFERROR(AND(OR(H1:K16,$V17)=TRUE,IF(SEARCH(H$1,$A17)>0,TRUE,FALSE)),"") | I17: =IFERROR(AND(OR(I1:K16,$V17)=TRUE,IF(SEARCH(I$1,$A17)>0,TRUE,FALSE)),"") | J17: =IFERROR(AND(OR(J1:K16,$V17)=TRUE,IF(SEARCH(J$1,$A17)>0,TRUE,FALSE)),"") -> FALSE | K17: =IFERROR(AND(OR(K1:K16,$V17)=TRUE,IF(SEARCH(K$1,$A17)>0,TRUE,FALSE)),"") | L17: =IFERROR(AND(OR(L1:L16,$V17)=TRUE,IF(SEARCH(L$1,$A17)>0,TRUE,FALSE)),"") | M17: =IFERROR(AND(OR(M1:P16,$V17)=TRUE,IF(SEARCH(M$1,$A17)>0,TRUE,FALSE)),"") | N17: =IFERROR(AND(OR(N1:P16,$V17)=TRUE,IF(SEARCH(N$1,$A17)>0,TRUE,FALSE)),"") | O17: =IFERROR(AND(OR(O1:P16,$V17)=TRUE,IF(SEARCH(O$1,$A17)>0,TRUE,FALSE)),"") -> FALSE | P17: =IFERROR(AND(OR(P1:P16,$V17)=TRUE,IF(SEARCH(P$1,$A17)>0,TRUE,FALSE)),"") | Q17: =IFERROR(AND(OR(Q1:R16,$V17)=TRUE,IF(SEARCH(Q$1,$A17)>0,TRUE,FALSE)),"") | R17: =IFERROR(AND(OR(R1:R16,$V17)=TRUE,IF(SEARCH(R$1,$A17)>0,TRUE,FALSE)),"") | S17: =IFERROR(AND(OR(S1:S16,$V17)=TRUE,IF(SEARCH(S$1,$A17)>0,TRUE,FALSE)),"") -> FALSE | T17: =COUNTIF(F17:S17,TRUE) -> 0 | U17: =IFERROR(AND(F17:S17), TRUE) -> FALSE | V17: =IF(E17="Y",TRUE,IF(E17="N",FALSE,0)) -> FALSE | W17: =IF(V17=FALSE, FALSE, U17) -> FALSE | X17: =IF(C17>'Overview (RESPONSES REQUIRED)'!$C$31,FALSE,TRUE) -> FALSE | Y17: =IF(D17>'Overview (RESPONSES REQUIRED)'!$C$34,FALSE,TRUE) -> FALSE | Z17: =AND(X17:Y17) -> FALSE | AA17: =IF(Z17=FALSE,"N",IF(W17=TRUE,"Y",IF(E17=0,"E","N"))) -> N
A18: CA_1A2-3A4-7C2-28A2 | B18: 4 | C18: 5 | D18: 12 | E18: =IF('LTE CA'!K20="Y", "Y", IF('LTE CA'!K20="N", "N", 0)) -> N | F18: =IFERROR(AND(OR(F1:G17,$V18)=TRUE,IF(SEARCH(F$1,$A18)>0,TRUE,FALSE)),"") -> FALSE | G18: =IFERROR(AND(OR(G1:G17,$V18)=TRUE,IF(SEARCH(G$1,$A18)>0,TRUE,FALSE)),"") | H18: =IFERROR(AND(OR(H1:K17,$V18)=TRUE,IF(SEARCH(H$1,$A18)>0,TRUE,FALSE)),"") | I18: =IFERROR(AND(OR(I1:K17,$V18)=TRUE,IF(SEARCH(I$1,$A18)>0,TRUE,FALSE)),"") -> FALSE | J18: =IFERROR(AND(OR(J1:K17,$V18)=TRUE,IF(SEARCH(J$1,$A18)>0,TRUE,FALSE)),"") | K18: =IFERROR(AND(OR(K1:K17,$V18)=TRUE,IF(SEARCH(K$1,$A18)>0,TRUE,FALSE)),"") | L18: =IFERROR(AND(OR(L1:L17,$V18)=TRUE,IF(SEARCH(L$1,$A18)>0,TRUE,FALSE)),"") | M18: =IFERROR(AND(OR(M1:P17,$V18)=TRUE,IF(SEARCH(M$1,$A18)>0,TRUE,FALSE)),"") | N18: =IFERROR(AND(OR(N1:P17,$V18)=TRUE,IF(SEARCH(N$1,$A18)>0,TRUE,FALSE)),"") | O18: =IFERROR(AND(OR(O1:P17,$V18)=TRUE,IF(SEARCH(O$1,$A18)>0,TRUE,FALSE)),"") -> FALSE | P18: =IFERROR(AND(OR(P1:P17,$V18)=TRUE,IF(SEARCH(P$1,$A18)>0,TRUE,FALSE)),"") | Q18: =IFERROR(AND(OR(Q1:R17,$V18)=TRUE,IF(SEARCH(Q$1,$A18)>0,TRUE,FALSE)),"") | R18: =IFERROR(AND(OR(R1:R17,$V18)=TRUE,IF(SEARCH(R$1,$A18)>0,TRUE,FALSE)),"") | S18: =IFERROR(AND(OR(S1:S17,$V18)=TRUE,IF(SEARCH(S$1,$A18)>0,TRUE,FALSE)),"") -> FALSE | T18: =COUNTIF(F18:S18,TRUE) -> 0 | U18: =IFERROR(AND(F18:S18), TRUE) -> FALSE | V18: =IF(E18="Y",TRUE,IF(E18="N",FALSE,0)) -> FALSE | W18: =IF(V18=FALSE, FALSE, U18) -> FALSE | X18: =IF(C18>'Overview (RESPONSES REQUIRED)'!$C$31,FALSE,TRUE) -> FALSE | Y18: =IF(D18>'Overview (RESPONSES REQUIRED)'!$C$34,FALSE,TRUE) -> FALSE | Z18: =AND(X18:Y18) -> FALSE | AA18: =IF(Z18=FALSE,"N",IF(W18=TRUE,"Y",IF(E18=0,"E","N"))) -> N
A19: CA_1A2-3C2-7A4-28A2 | B19: 4 | C19: 5 | D19: 12 | E19: =IF('LTE CA'!K21="Y", "Y", IF('LTE CA'!K21="N", "N", 0)) -> N | F19: =IFERROR(AND(OR(F1:G18,$V19)=TRUE,IF(SEARCH(F$1,$A19)>0,TRUE,FALSE)),"") -> FALSE | G19: =IFERROR(AND(OR(G1:G18,$V19)=TRUE,IF(SEARCH(G$1,$A19)>0,TRUE,FALSE)),"") | H19: =IFERROR(AND(OR(H1:K18,$V19)=TRUE,IF(SEARCH(H$1,$A19)>0,TRUE,FALSE)),"") | I19: =IFERROR(AND(OR(I1:K18,$V19)=TRUE,IF(SEARCH(I$1,$A19)>0,TRUE,FALSE)),"") | J19: =IFERROR(AND(OR(J1:K18,$V19)=TRUE,IF(SEARCH(J$1,$A19)>0,TRUE,FALSE)),"") -> FALSE | K19: =IFERROR(AND(OR(K1:K18,$V19)=TRUE,IF(SEARCH(K$1,$A19)>0,TRUE,FALSE)),"") | L19: =IFERROR(AND(OR(L1:L18,$V19)=TRUE,IF(SEARCH(L$1,$A19)>0,TRUE,FALSE)),"") | M19: =IFERROR(AND(OR(M1:P18,$V19)=TRUE,IF(SEARCH(M$1,$A19)>0,TRUE,FALSE)),"") | N19: =IFERROR(AND(OR(N1:P18,$V19)=TRUE,IF(SEARCH(N$1,$A19)>0,TRUE,FALSE)),"") -> FALSE | O19: =IFERROR(AND(OR(O1:P18,$V19)=TRUE,IF(SEARCH(O$1,$A19)>0,TRUE,FALSE)),"") | P19: =IFERROR(AND(OR(P1:P18,$V19)=TRUE,IF(SEARCH(P$1,$A19)>0,TRUE,FALSE)),"") | Q19: =IFERROR(AND(OR(Q1:R18,$V19)=TRUE,IF(SEARCH(Q$1,$A19)>0,TRUE,FALSE)),"") | R19: =IFERROR(AND(OR(R1:R18,$V19)=TRUE,IF(SEARCH(R$1,$A19)>0,TRUE,FALSE)),"") | S19: =IFERROR(AND(OR(S1:S18,$V19)=TRUE,IF(SEARCH(S$1,$A19)>0,TRUE,FALSE)),"") -> FALSE | T19: =COUNTIF(F19:S19,TRUE) -> 0 | U19: =IFERROR(AND(F19:S19), TRUE) -> FALSE | V19: =IF(E19="Y",TRUE,IF(E19="N",FALSE,0)) -> FALSE | W19: =IF(V19=FALSE, FALSE, U19) -> FALSE | X19: =IF(C19>'Overview (RESPONSES REQUIRED)'!$C$31,FALSE,TRUE) -> FALSE | Y19: =IF(D19>'Overview (RESPONSES REQUIRED)'!$C$34,FALSE,TRUE) -> FALSE | Z19: =AND(X19:Y19) -> FALSE | AA19: =IF(Z19=FALSE,"N",IF(W19=TRUE,"Y",IF(E19=0,"E","N"))) -> N
A20: CA_1A2-3A4-7A4-28A2 | B20: 4 | C20: 4 | D20: 12 | E20: =IF('LTE CA'!K22="Y", "Y", IF('LTE CA'!K22="N", "N", 0)) -> N | F20: =IFERROR(AND(OR(F1:G19,$V20)=TRUE,IF(SEARCH(F$1,$A20)>0,TRUE,FALSE)),"") -> FALSE | G20: =IFERROR(AND(OR(G1:G19,$V20)=TRUE,IF(SEARCH(G$1,$A20)>0,TRUE,FALSE)),"") | H20: =IFERROR(AND(OR(H1:K19,$V20)=TRUE,IF(SEARCH(H$1,$A20)>0,TRUE,FALSE)),"") | I20: =IFERROR(AND(OR(I1:K19,$V20)=TRUE,IF(SEARCH(I$1,$A20)>0,TRUE,FALSE)),"") -> FALSE | J20: =IFERROR(AND(OR(J1:K19,$V20)=TRUE,IF(SEARCH(J$1,$A20)>0,TRUE,FALSE)),"") | K20: =IFERROR(AND(OR(K1:K19,$V20)=TRUE,IF(SEARCH(K$1,$A20)>0,TRUE,FALSE)),"") | L20: =IFERROR(AND(OR(L1:L19,$V20)=TRUE,IF(SEARCH(L$1,$A20)>0,TRUE,FALSE)),"") | M20: =IFERROR(AND(OR(M1:P19,$V20)=TRUE,IF(SEARCH(M$1,$A20)>0,TRUE,FALSE)),"") | N20: =IFERROR(AND(OR(N1:P19,$V20)=TRUE,IF(SEARCH(N$1,$A20)>0,TRUE,FALSE)),"") -> FALSE | O20: =IFERROR(AND(OR(O1:P19,$V20)=TRUE,IF(SEARCH(O$1,$A20)>0,TRUE,FALSE)),"") | P20: =IFERROR(AND(OR(P1:P19,$V20)=TRUE,IF(SEARCH(P$1,$A20)>0,TRUE,FALSE)),"") | Q20: =IFERROR(AND(OR(Q1:R19,$V20)=TRUE,IF(SEARCH(Q$1,$A20)>0,TRUE,FALSE)),"") | R20: =IFERROR(AND(OR(R1:R19,$V20)=TRUE,IF(SEARCH(R$1,$A20)>0,TRUE,FALSE)),"") | S20: =IFERROR(AND(OR(S1:S19,$V20)=TRUE,IF(SEARCH(S$1,$A20)>0,TRUE,FALSE)),"") -> FALSE | T20: =COUNTIF(F20:S20,TRUE) -> 0 | U20: =IFERROR(AND(F20:S20), TRUE) -> FALSE | V20: =IF(E20="Y",TRUE,IF(E20="N",FALSE,0)) -> FALSE | W20: =IF(V20=FALSE, FALSE, U20) -> FALSE | X20: =IF(C20>'Overview (RESPONSES REQUIRED)'!$C$31,FALSE,TRUE) -> FALSE | Y20: =IF(D20>'Overview (RESPONSES REQUIRED)'!$C$34,FALSE,TRUE) -> FALSE | Z20: =AND(X20:Y20) -> FALSE | AA20: =IF(Z20=FALSE,"N",IF(W20=TRUE,"Y",IF(E20=0,"E","N"))) -> N
A21: CA_1A4-3A2-7A4-28A2 | B21: 4 | C21: 4 | D21: 12 | E21: =IF('LTE CA'!K23="Y", "Y", IF('LTE CA'!K23="N", "N", 0)) -> N | F21: =IFERROR(AND(OR(F1:G20,$V21)=TRUE,IF(SEARCH(F$1,$A21)>0,TRUE,FALSE)),"") | G21: =IFERROR(AND(OR(G1:G20,$V21)=TRUE,IF(SEARCH(G$1,$A21)>0,TRUE,FALSE)),"") -> FALSE | H21: =IFERROR(AND(OR(H1:K20,$V21)=TRUE,IF(SEARCH(H$1,$A21)>0,TRUE,FALSE)),"") -> FALSE | I21: =IFERROR(AND(OR(I1:K20,$V21)=TRUE,IF(SEARCH(I$1,$A21)>0,TRUE,FALSE)),"") | J21: =IFERROR(AND(OR(J1:K20,$V21)=TRUE,IF(SEARCH(J$1,$A21)>0,TRUE,FALSE)),"") | K21: =IFERROR(AND(OR(K1:K20,$V21)=TRUE,IF(SEARCH(K$1,$A21)>0,TRUE,FALSE)),"") | L21: =IFERROR(AND(OR(L1:L20,$V21)=TRUE,IF(SEARCH(L$1,$A21)>0,TRUE,FALSE)),"") | M21: =IFERROR(AND(OR(M1:P20,$V21)=TRUE,IF(SEARCH(M$1,$A21)>0,TRUE,FALSE)),"") | N21: =IFERROR(AND(OR(N1:P20,$V21)=TRUE,IF(SEARCH(N$1,$A21)>0,TRUE,FALSE)),"") -> FALSE | O21: =IFERROR(AND(OR(O1:P20,$V21)=TRUE,IF(SEARCH(O$1,$A21)>0,TRUE,FALSE)),"") | P21: =IFERROR(AND(OR(P1:P20,$V21)=TRUE,IF(SEARCH(P$1,$A21)>0,TRUE,FALSE)),"") | Q21: =IFERROR(AND(OR(Q1:R20,$V21)=TRUE,IF(SEARCH(Q$1,$A21)>0,TRUE,FALSE)),"") | R21: =IFERROR(AND(OR(R1:R20,$V21)=TRUE,IF(SEARCH(R$1,$A21)>0,TRUE,FALSE)),"") | S21: =IFERROR(AND(OR(S1:S20,$V21)=TRUE,IF(SEARCH(S$1,$A21)>0,TRUE,FALSE)),"") -> FALSE | T21: =COUNTIF(F21:S21,TRUE) -> 0 | U21: =IFERROR(AND(F21:S21), TRUE) -> FALSE | V21: =IF(E21="Y",TRUE,IF(E21="N",FALSE,0)) -> FALSE | W21: =IF(V21=FALSE, FALSE, U21) -> FALSE | X21: =IF(C21>'Overview (RESPONSES REQUIRED)'!$C$31,FALSE,TRUE) -> FALSE | Y21: =IF(D21>'Overview (RESPONSES REQUIRED)'!$C$34,FALSE,TRUE) -> FALSE | Z21: =AND(X21:Y21) -> FALSE | AA21: =IF(Z21=FALSE,"N",IF(W21=TRUE,"Y",IF(E21=0,"E","N"))) -> N
A22: CA_1A4-3A4-7A2-28A2 | B22: 4 | C22: 4 | D22: 12 | E22: =IF('LTE CA'!K24="Y", "Y", IF('LTE CA'!K24="N", "N", 0)) -> N | F22: =IFERROR(AND(OR(F1:G21,$V22)=TRUE,IF(SEARCH(F$1,$A22)>0,TRUE,FALSE)),"") | G22: =IFERROR(AND(OR(G1:G21,$V22)=TRUE,IF(SEARCH(G$1,$A22)>0,TRUE,FALSE)),"") -> FALSE | H22: =IFERROR(AND(OR(H1:K21,$V22)=TRUE,IF(SEARCH(H$1,$A22)>0,TRUE,FALSE)),"") | I22: =IFERROR(AND(OR(I1:K21,$V22)=TRUE,IF(SEARCH(I$1,$A22)>0,TRUE,FALSE)),"") -> FALSE | J22: =IFERROR(AND(OR(J1:K21,$V22)=TRUE,IF(SEARCH(J$1,$A22)>0,TRUE,FALSE)),"") | K22: =IFERROR(AND(OR(K1:K21,$V22)=TRUE,IF(SEARCH(K$1,$A22)>0,TRUE,FALSE)),"") | L22: =IFERROR(AND(OR(L1:L21,$V22)=TRUE,IF(SEARCH(L$1,$A22)>0,TRUE,FALSE)),"") | M22: =IFERROR(AND(OR(M1:P21,$V22)=TRUE,IF(SEARCH(M$1,$A22)>0,TRUE,FALSE)),"") -> FALSE | N22: =IFERROR(AND(OR(N1:P21,$V22)=TRUE,IF(SEARCH(N$1,$A22)>0,TRUE,FALSE)),"") | O22: =IFERROR(AND(OR(O1:P21,$V22)=TRUE,IF(SEARCH(O$1,$A22)>0,TRUE,FALSE)),"") | P22: =IFERROR(AND(OR(P1:P21,$V22)=TRUE,IF(SEARCH(P$1,$A22)>0,TRUE,FALSE)),"") | Q22: =IFERROR(AND(OR(Q1:R21,$V22)=TRUE,IF(SEARCH(Q$1,$A22)>0,TRUE,FALSE)),"") | R22: =IFERROR(AND(OR(R1:R21,$V22)=TRUE,IF(SEARCH(R$1,$A22)>0,TRUE,FALSE)),"") | S22: =IFERROR(AND(OR(S1:S21,$V22)=TRUE,IF(SEARCH(S$1,$A22)>0,TRUE,FALSE)),"") -> FALSE | T22: =COUNTIF(F22:S22,TRUE) -> 0 | U22: =IFERROR(AND(F22:S22), TRUE) -> FALSE | V22: =IF(E22="Y",TRUE,IF(E22="N",FALSE,0)) -> FALSE | W22: =IF(V22=FALSE, FALSE, U22) -> FALSE | X22: =IF(C22>'Overview (RESPONSES REQUIRED)'!$C$31,FALSE,TRUE) -> FALSE | Y22: =IF(D22>'Overview (RESPONSES REQUIRED)'!$C$34,FALSE,TRUE) -> FALSE | Z22: =AND(X22:Y22) -> FALSE | AA22: =IF(Z22=FALSE,"N",IF(W22=TRUE,"Y",IF(E22=0,"E","N"))) -> N
A23: CA_1A2-3A2-7C2-28A2 | B23: 4 | C23: 5 | D23: 10 | E23: =IF('LTE CA'!K25="Y", "Y", IF('LTE CA'!K25="N", "N", 0)) -> N | F23: =IFERROR(AND(OR(F1:G22,$V23)=TRUE,IF(SEARCH(F$1,$A23)>0,TRUE,FALSE)),"") -> FALSE | G23: =IFERROR(AND(OR(G1:G22,$V23)=TRUE,IF(SEARCH(G$1,$A23)>0,TRUE,FALSE)),"") | H23: =IFERROR(AND(OR(H1:K22,$V23)=TRUE,IF(SEARCH(H$1,$A23)>0,TRUE,FALSE)),"") -> FALSE | I23: =IFERROR(AND(OR(I1:K22,$V23)=TRUE,IF(SEARCH(I$1,$A23)>0,TRUE,FALSE)),"") | J23: =IFERROR(AND(OR(J1:K22,$V23)=TRUE,IF(SEARCH(J$1,$A23)>0,TRUE,FALSE)),"") | K23: =IFERROR(AND(OR(K1:K22,$V23)=TRUE,IF(SEARCH(K$1,$A23)>0,TRUE,FALSE)),"") | L23: =IFERROR(AND(OR(L1:L22,$V23)=TRUE,IF(SEARCH(L$1,$A23)>0,TRUE,FALSE)),"") | M23: =IFERROR(AND(OR(M1:P22,$V23)=TRUE,IF(SEARCH(M$1,$A23)>0,TRUE,FALSE)),"") | N23: =IFERROR(AND(OR(N1:P22,$V23)=TRUE,IF(SEARCH(N$1,$A23)>0,TRUE,FALSE)),"") | O23: =IFERROR(AND(OR(O1:P22,$V23)=TRUE,IF(SEARCH(O$1,$A23)>0,TRUE,FALSE)),"") -> FALSE | P23: =IFERROR(AND(OR(P1:P22,$V23)=TRUE,IF(SEARCH(P$1,$A23)>0,TRUE,FALSE)),"") | Q23: =IFERROR(AND(OR(Q1:R22,$V23)=TRUE,IF(SEARCH(Q$1,$A23)>0,TRUE,FALSE)),"") | R23: =IFERROR(AND(OR(R1:R22,$V23)=TRUE,IF(SEARCH(R$1,$A23)>0,TRUE,FALSE)),"") | S23: =IFERROR(AND(OR(S1:S22,$V23)=TRUE,IF(SEARCH(S$1,$A23)>0,TRUE,FALSE)),"") -> FALSE | T23: =COUNTIF(F23:S23,TRUE) -> 0 | U23: =IFERROR(AND(F23:S23), TRUE) -> FALSE | V23: =IF(E23="Y",TRUE,IF(E23="N",FALSE,0)) -> FALSE | W23: =IF(V23=FALSE, FALSE, U23) -> FALSE | X23: =IF(C23>'Overview (RESPONSES REQUIRED)'!$C$31,FALSE,TRUE) -> FALSE | Y23: =IF(D23>'Overview (RESPONSES REQUIRED)'!$C$34,FALSE,TRUE) -> FALSE | Z23: =AND(X23:Y23) -> FALSE | AA23: =IF(Z23=FALSE,"N",IF(W23=TRUE,"Y",IF(E23=0,"E","N"))) -> N
A24: CA_1A2-3C2-7A2-28A2 | B24: 4 | C24: 5 | D24: 10 | E24: =IF('LTE CA'!K26="Y", "Y", IF('LTE CA'!K26="N", "N", 0)) -> N | F24: =IFERROR(AND(OR(F1:G23,$V24)=TRUE,IF(SEARCH(F$1,$A24)>0,TRUE,FALSE)),"") -> FALSE | G24: =IFERROR(AND(OR(G1:G23,$V24)=TRUE,IF(SEARCH(G$1,$A24)>0,TRUE,FALSE)),"") | H24: =IFERROR(AND(OR(H1:K23,$V24)=TRUE,IF(SEARCH(H$1,$A24)>0,TRUE,FALSE)),"") | I24: =IFERROR(AND(OR(I1:K23,$V24)=TRUE,IF(SEARCH(I$1,$A24)>0,TRUE,FALSE)),"") | J24: =IFERROR(AND(OR(J1:K23,$V24)=TRUE,IF(SEARCH(J$1,$A24)>0,TRUE,FALSE)),"") -> FALSE | K24: =IFERROR(AND(OR(K1:K23,$V24)=TRUE,IF(SEARCH(K$1,$A24)>0,TRUE,FALSE)),"") | L24: =IFERROR(AND(OR(L1:L23,$V24)=TRUE,IF(SEARCH(L$1,$A24)>0,TRUE,FALSE)),"") | M24: =IFERROR(AND(OR(M1:P23,$V24)=TRUE,IF(SEARCH(M$1,$A24)>0,TRUE,FALSE)),"") -> FALSE | N24: =IFERROR(AND(OR(N1:P23,$V24)=TRUE,IF(SEARCH(N$1,$A24)>0,TRUE,FALSE)),"") | O24: =IFERROR(AND(OR(O1:P23,$V24)=TRUE,IF(SEARCH(O$1,$A24)>0,TRUE,FALSE)),"") | P24: =IFERROR(AND(OR(P1:P23,$V24)=TRUE,IF(SEARCH(P$1,$A24)>0,TRUE,FALSE)),"") | Q24: =IFERROR(AND(OR(Q1:R23,$V24)=TRUE,IF(SEARCH(Q$1,$A24)>0,TRUE,FALSE)),"") | R24: =IFERROR(AND(OR(R1:R23,$V24)=TRUE,IF(SEARCH(R$1,$A24)>0,TRUE,FALSE)),"") | S24: =IFERROR(AND(OR(S1:S23,$V24)=TRUE,IF(SEARCH(S$1,$A24)>0,TRUE,FALSE)),"") -> FALSE | T24: =COUNTIF(F24:S24,TRUE) -> 0 | U24: =IFERROR(AND(F24:S24), TRUE) -> FALSE | V24: =IF(E24="Y",TRUE,IF(E24="N",FALSE,0)) -> FALSE | W24: =IF(V24=FALSE, FALSE, U24) -> FALSE | X24: =IF(C24>'Overview (RESPONSES REQUIRED)'!$C$31,FALSE,TRUE) -> FALSE | Y24: =IF(D24>'Overview (RESPONSES REQUIRED)'!$C$34,FALSE,TRUE) -> FALSE | Z24: =AND(X24:Y24) -> FALSE | AA24: =IF(Z24=FALSE,"N",IF(W24=TRUE,"Y",IF(E24=0,"E","N"))) -> N
A25: CA_1A2-3A4-7A2-28A2 | B25: 4 | C25: 4 | D25: 10 | E25: =IF('LTE CA'!K27="Y", "Y", IF('LTE CA'!K27="N", "N", 0)) -> N | F25: =IFERROR(AND(OR(F1:G24,$V25)=TRUE,IF(SEARCH(F$1,$A25)>0,TRUE,FALSE)),"") -> FALSE | G25: =IFERROR(AND(OR(G1:G24,$V25)=TRUE,IF(SEARCH(G$1,$A25)>0,TRUE,FALSE)),"") | H25: =IFERROR(AND(OR(H1:K24,$V25)=TRUE,IF(SEARCH(H$1,$A25)>0,TRUE,FALSE)),"") | I25: =IFERROR(AND(OR(I1:K24,$V25)=TRUE,IF(SEARCH(I$1,$A25)>0,TRUE,FALSE)),"") -> FALSE | J25: =IFERROR(AND(OR(J1:K24,$V25)=TRUE,IF(SEARCH(J$1,$A25)>0,TRUE,FALSE)),"") | K25: =IFERROR(AND(OR(K1:K24,$V25)=TRUE,IF(SEARCH(K$1,$A25)>0,TRUE,FALSE)),"") | L25: =IFERROR(AND(OR(L1:L24,$V25)=TRUE,IF(SEARCH(L$1,$A25)>0,TRUE,FALSE)),"") | M25: =IFERROR(AND(OR(M1:P24,$V25)=TRUE,IF(SEARCH(M$1,$A25)>0,TRUE,FALSE)),"") -> FALSE | N25: =IFERROR(AND(OR(N1:P24,$V25)=TRUE,IF(SEARCH(N$1,$A25)>0,TRUE,FALSE)),"") | O25: =IFERROR(AND(OR(O1:P24,$V25)=TRUE,IF(SEARCH(O$1,$A25)>0,TRUE,FALSE)),"") | P25: =IFERROR(AND(OR(P1:P24,$V25)=TRUE,IF(SEARCH(P$1,$A25)>0,TRUE,FALSE)),"") | Q25: =IFERROR(AND(OR(Q1:R24,$V25)=TRUE,IF(SEARCH(Q$1,$A25)>0,TRUE,FALSE)),"") | R25: =IFERROR(AND(OR(R1:R24,$V25)=TRUE,IF(SEARCH(R$1,$A25)>0,TRUE,FALSE)),"") | S25: =IFERROR(AND(OR(S1:S24,$V25)=TRUE,IF(SEARCH(S$1,$A25)>0,TRUE,FALSE)),"") -> FALSE | T25: =COUNTIF(F25:S25,TRUE) -> 0 | U25: =IFERROR(AND(F25:S25), TRUE) -> FALSE | V25: =IF(E25="Y",TRUE,IF(E25="N",FALSE,0)) -> FALSE | W25: =IF(V25=FALSE, FALSE, U25) -> FALSE | X25: =IF(C25>'Overview (RESPONSES REQUIRED)'!$C$31,FALSE,TRUE) -> FALSE | Y25: =IF(D25>'Overview (RESPONSES REQUIRED)'!$C$34,FALSE,TRUE) -> FALSE | Z25: =AND(X25:Y25) -> FALSE | AA25: =IF(Z25=FALSE,"N",IF(W25=TRUE,"Y",IF(E25=0,"E","N"))) -> N
A26: CA_1A2-3A2-7A4-28A2 | B26: 4 | C26: 4 | D26: 10 | E26: =IF('LTE CA'!K28="Y", "Y", IF('LTE CA'!K28="N", "N", 0)) -> N | F26: =IFERROR(AND(OR(F1:G25,$V26)=TRUE,IF(SEARCH(F$1,$A26)>0,TRUE,FALSE)),"") -> FALSE | G26: =IFERROR(AND(OR(G1:G25,$V26)=TRUE,IF(SEARCH(G$1,$A26)>0,TRUE,FALSE)),"") | H26: =IFERROR(AND(OR(H1:K25,$V26)=TRUE,IF(SEARCH(H$1,$A26)>0,TRUE,FALSE)),"") -> FALSE | I26: =IFERROR(AND(OR(I1:K25,$V26)=TRUE,IF(SEARCH(I$1,$A26)>0,TRUE,FALSE)),"") | J26: =IFERROR(AND(OR(J1:K25,$V26)=TRUE,IF(SEARCH(J$1,$A26)>0,TRUE,FALSE)),"") | K26: =IFERROR(AND(OR(K1:K25,$V26)=TRUE,IF(SEARCH(K$1,$A26)>0,TRUE,FALSE)),"") | L26: =IFERROR(AND(OR(L1:L25,$V26)=TRUE,IF(SEARCH(L$1,$A26)>0,TRUE,FALSE)),"") | M26: =IFERROR(AND(OR(M1:P25,$V26)=TRUE,IF(SEARCH(M$1,$A26)>0,TRUE,FALSE)),"") | N26: =IFERROR(AND(OR(N1:P25,$V26)=TRUE,IF(SEARCH(N$1,$A26)>0,TRUE,FALSE)),"") -> FALSE | O26: =IFERROR(AND(OR(O1:P25,$V26)=TRUE,IF(SEARCH(O$1,$A26)>0,TRUE,FALSE)),"") | P26: =IFERROR(AND(OR(P1:P25,$V26)=TRUE,IF(SEARCH(P$1,$A26)>0,TRUE,FALSE)),"") | Q26: =IFERROR(AND(OR(Q1:R25,$V26)=TRUE,IF(SEARCH(Q$1,$A26)>0,TRUE,FALSE)),"") | R26: =IFERROR(AND(OR(R1:R25,$V26)=TRUE,IF(SEARCH(R$1,$A26)>0,TRUE,FALSE)),"") | S26: =IFERROR(AND(OR(S1:S25,$V26)=TRUE,IF(SEARCH(S$1,$A26)>0,TRUE,FALSE)),"") -> FALSE | T26: =COUNTIF(F26:S26,TRUE) -> 0 | U26: =IFERROR(AND(F26:S26), TRUE) -> FALSE | V26: =IF(E26="Y",TRUE,IF(E26="N",FALSE,0)) -> FALSE | W26: =IF(V26=FALSE, FALSE, U26) -> FALSE | X26: =IF(C26>'Overview (RESPONSES REQUIRED)'!$C$31,FALSE,TRUE) -> FALSE | Y26: =IF(D26>'Overview (RESPONSES REQUIRED)'!$C$34,FALSE,TRUE) -> FALSE | Z26: =AND(X26:Y26) -> FALSE | AA26: =IF(Z26=FALSE,"N",IF(W26=TRUE,"Y",IF(E26=0,"E","N"))) -> N
A27: CA_1A4-3A2-7A2-28A2 | B27: 4 | C27: 4 | D27: 10 | E27: =IF('LTE CA'!K29="Y", "Y", IF('LTE CA'!K29="N", "N", 0)) -> N | F27: =IFERROR(AND(OR(F1:G26,$V27)=TRUE,IF(SEARCH(F$1,$A27)>0,TRUE,FALSE)),"") | G27: =IFERROR(AND(OR(G1:G26,$V27)=TRUE,IF(SEARCH(G$1,$A27)>0,TRUE,FALSE)),"") -> FALSE | H27: =IFERROR(AND(OR(H1:K26,$V27)=TRUE,IF(SEARCH(H$1,$A27)>0,TRUE,FALSE)),"") -> FALSE | I27: =IFERROR(AND(OR(I1:K26,$V27)=TRUE,IF(SEARCH(I$1,$A27)>0,TRUE,FALSE)),"") | J27: =IFERROR(AND(OR(J1:K26,$V27)=TRUE,IF(SEARCH(J$1,$A27)>0,TRUE,FALSE)),"") | K27: =IFERROR(AND(OR(K1:K26,$V27)=TRUE,IF(SEARCH(K$1,$A27)>0,TRUE,FALSE)),"") | L27: =IFERROR(AND(OR(L1:L26,$V27)=TRUE,IF(SEARCH(L$1,$A27)>0,TRUE,FALSE)),"") | M27: =IFERROR(AND(OR(M1:P26,$V27)=TRUE,IF(SEARCH(M$1,$A27)>0,TRUE,FALSE)),"") -> FALSE | N27: =IFERROR(AND(OR(N1:P26,$V27)=TRUE,IF(SEARCH(N$1,$A27)>0,TRUE,FALSE)),"") | O27: =IFERROR(AND(OR(O1:P26,$V27)=TRUE,IF(SEARCH(O$1,$A27)>0,TRUE,FALSE)),"") | P27: =IFERROR(AND(OR(P1:P26,$V27)=TRUE,IF(SEARCH(P$1,$A27)>0,TRUE,FALSE)),"") | Q27: =IFERROR(AND(OR(Q1:R26,$V27)=TRUE,IF(SEARCH(Q$1,$A27)>0,TRUE,FALSE)),"") | R27: =IFERROR(AND(OR(R1:R26,$V27)=TRUE,IF(SEARCH(R$1,$A27)>0,TRUE,FALSE)),"") | S27: =IFERROR(AND(OR(S1:S26,$V27)=TRUE,IF(SEARCH(S$1,$A27)>0,TRUE,FALSE)),"") -> FALSE | T27: =COUNTIF(F27:S27,TRUE) -> 0 | U27: =IFERROR(AND(F27:S27), TRUE) -> FALSE | V27: =IF(E27="Y",TRUE,IF(E27="N",FALSE,0)) -> FALSE | W27: =IF(V27=FALSE, FALSE, U27) -> FALSE | X27: =IF(C27>'Overview (RESPONSES REQUIRED)'!$C$31,FALSE,TRUE) -> FALSE | Y27: =IF(D27>'Overview (RESPONSES REQUIRED)'!$C$34,FALSE,TRUE) -> FALSE | Z27: =AND(X27:Y27) -> FALSE | AA27: =IF(Z27=FALSE,"N",IF(W27=TRUE,"Y",IF(E27=0,"E","N"))) -> N
A28: CA_1A2-3A2-7A2-28A2 | B28: 4 | C28: 4 | D28: 8 | E28: =IF('LTE CA'!K30="Y", "Y", IF('LTE CA'!K30="N", "N", 0)) -> N | F28: =IFERROR(AND(OR(F1:G27,$V28)=TRUE,IF(SEARCH(F$1,$A28)>0,TRUE,FALSE)),"") -> FALSE | G28: =IFERROR(AND(OR(G1:G27,$V28)=TRUE,IF(SEARCH(G$1,$A28)>0,TRUE,FALSE)),"") | H28: =IFERROR(AND(OR(H1:K27,$V28)=TRUE,IF(SEARCH(H$1,$A28)>0,TRUE,FALSE)),"") -> FALSE | I28: =IFERROR(AND(OR(I1:K27,$V28)=TRUE,IF(SEARCH(I$1,$A28)>0,TRUE,FALSE)),"") | J28: =IFERROR(AND(OR(J1:K27,$V28)=TRUE,IF(SEARCH(J$1,$A28)>0,TRUE,FALSE)),"") | K28: =IFERROR(AND(OR(K1:K27,$V28)=TRUE,IF(SEARCH(K$1,$A28)>0,TRUE,FALSE)),"") | L28: =IFERROR(AND(OR(L1:L27,$V28)=TRUE,IF(SEARCH(L$1,$A28)>0,TRUE,FALSE)),"") | M28: =IFERROR(AND(OR(M1:P27,$V28)=TRUE,IF(SEARCH(M$1,$A28)>0,TRUE,FALSE)),"") -> FALSE | N28: =IFERROR(AND(OR(N1:P27,$V28)=TRUE,IF(SEARCH(N$1,$A28)>0,TRUE,FALSE)),"") | O28: =IFERROR(AND(OR(O1:P27,$V28)=TRUE,IF(SEARCH(O$1,$A28)>0,TRUE,FALSE)),"") | P28: =IFERROR(AND(OR(P1:P27,$V28)=TRUE,IF(SEARCH(P$1,$A28)>0,TRUE,FALSE)),"") | Q28: =IFERROR(AND(OR(Q1:R27,$V28)=TRUE,IF(SEARCH(Q$1,$A28)>0,TRUE,FALSE)),"") | R28: =IFERROR(AND(OR(R1:R27,$V28)=TRUE,IF(SEARCH(R$1,$A28)>0,TRUE,FALSE)),"") | S28: =IFERROR(AND(OR(S1:S27,$V28)=TRUE,IF(SEARCH(S$1,$A28)>0,TRUE,FALSE)),"") -> FALSE | T28: =COUNTIF(F28:S28,TRUE) -> 0 | U28: =IFERROR(AND(F28:S28), TRUE) -> FALSE | V28: =IF(E28="Y",TRUE,IF(E28="N",FALSE,0)) -> FALSE | W28: =IF(V28=FALSE, FALSE, U28) -> FALSE | X28: =IF(C28>'Overview (RESPONSES REQUIRED)'!$C$31,FALSE,TRUE) -> FALSE | Y28: =IF(D28>'Overview (RESPONSES REQUIRED)'!$C$34,FALSE,TRUE) -> FALSE | Z28: =AND(X28:Y28) -> FALSE | AA28: =IF(Z28=FALSE,"N",IF(W28=TRUE,"Y",IF(E28=0,"E","N"))) -> N
A29: CA_1A4-3C4-7C4 | B29: 3 | C29: 5 | D29: 20 | E29: =IF('LTE CA'!K31="Y", "Y", IF('LTE CA'!K31="N", "N", 0)) -> N | F29: =IFERROR(AND(OR(F1:G28,$V29)=TRUE,IF(SEARCH(F$1,$A29)>0,TRUE,FALSE)),"") | G29: =IFERROR(AND(OR(G1:G28,$V29)=TRUE,IF(SEARCH(G$1,$A29)>0,TRUE,FALSE)),"") -> FALSE | H29: =IFERROR(AND(OR(H1:K28,$V29)=TRUE,IF(SEARCH(H$1,$A29)>0,TRUE,FALSE)),"") | I29: =IFERROR(AND(OR(I1:K28,$V29)=TRUE,IF(SEARCH(I$1,$A29)>0,TRUE,FALSE)),"") | J29: =IFERROR(AND(OR(J1:K28,$V29)=TRUE,IF(SEARCH(J$1,$A29)>0,TRUE,FALSE)),"") | K29: =IFERROR(AND(OR(K1:K28,$V29)=TRUE,IF(SEARCH(K$1,$A29)>0,TRUE,FALSE)),"") -> FALSE | L29: =IFERROR(AND(OR(L1:L28,$V29)=TRUE,IF(SEARCH(L$1,$A29)>0,TRUE,FALSE)),"") | M29: =IFERROR(AND(OR(M1:P28,$V29)=TRUE,IF(SEARCH(M$1,$A29)>0,TRUE,FALSE)),"") | N29: =IFERROR(AND(OR(N1:P28,$V29)=TRUE,IF(SEARCH(N$1,$A29)>0,TRUE,FALSE)),"") | O29: =IFERROR(AND(OR(O1:P28,$V29)=TRUE,IF(SEARCH(O$1,$A29)>0,TRUE,FALSE)),"") | P29: =IFERROR(AND(OR(P1:P28,$V29)=TRUE,IF(SEARCH(P$1,$A29)>0,TRUE,FALSE)),"") -> FALSE | Q29: =IFERROR(AND(OR(Q1:R28,$V29)=TRUE,IF(SEARCH(Q$1,$A29)>0,TRUE,FALSE)),"") | R29: =IFERROR(AND(OR(R1:R28,$V29)=TRUE,IF(SEARCH(R$1,$A29)>0,TRUE,FALSE)),"") | S29: =IFERROR(AND(OR(S1:S28,$V29)=TRUE,IF(SEARCH(S$1,$A29)>0,TRUE,FALSE)),"") | T29: =COUNTIF(F29:S29,TRUE) -> 0 | U29: =IFERROR(AND(F29:S29), TRUE) -> FALSE | V29: =IF(E29="Y",TRUE,IF(E29="N",FALSE,0)) -> FALSE | W29: =IF(V29=FALSE, FALSE, U29) -> FALSE | X29: =IF(C29>'Overview (RESPONSES REQUIRED)'!$C$31,FALSE,TRUE) -> FALSE | Y29: =IF(D29>'Overview (RESPONSES REQUIRED)'!$C$34,FALSE,TRUE) -> FALSE | Z29: =AND(X29:Y29) -> FALSE | AA29: =IF(Z29=FALSE,"N",IF(W29=TRUE,"Y",IF(E29=0,"E","N"))) -> N
A30: CA_3C4-7C4-28A2 | B30: 3 | C30: 5 | D30: 18 | E30: =IF('LTE CA'!K32="Y", "Y", IF('LTE CA'!K32="N", "N", 0)) -> N | F30: =IFERROR(AND(OR(F1:G29,$V30)=TRUE,IF(SEARCH(F$1,$A30)>0,TRUE,FALSE)),"") | G30: =IFERROR(AND(OR(G1:G29,$V30)=TRUE,IF(SEARCH(G$1,$A30)>0,TRUE,FALSE)),"") | H30: =IFERROR(AND(OR(H1:K29,$V30)=TRUE,IF(SEARCH(H$1,$A30)>0,TRUE,FALSE)),"") | I30: =IFERROR(AND(OR(I1:K29,$V30)=TRUE,IF(SEARCH(I$1,$A30)>0,TRUE,FALSE)),"") | J30: =IFERROR(AND(OR(J1:K29,$V30)=TRUE,IF(SEARCH(J$1,$A30)>0,TRUE,FALSE)),"") | K30: =IFERROR(AND(OR(K1:K29,$V30)=TRUE,IF(SEARCH(K$1,$A30)>0,TRUE,FALSE)),"") -> FALSE | L30: =IFERROR(AND(OR(L1:L29,$V30)=TRUE,IF(SEARCH(L$1,$A30)>0,TRUE,FALSE)),"") | M30: =IFERROR(AND(OR(M1:P29,$V30)=TRUE,IF(SEARCH(M$1,$A30)>0,TRUE,FALSE)),"") | N30: =IFERROR(AND(OR(N1:P29,$V30)=TRUE,IF(SEARCH(N$1,$A30)>0,TRUE,FALSE)),"") | O30: =IFERROR(AND(OR(O1:P29,$V30)=TRUE,IF(SEARCH(O$1,$A30)>0,TRUE,FALSE)),"") | P30: =IFERROR(AND(OR(P1:P29,$V30)=TRUE,IF(SEARCH(P$1,$A30)>0,TRUE,FALSE)),"") -> FALSE | Q30: =IFERROR(AND(OR(Q1:R29,$V30)=TRUE,IF(SEARCH(Q$1,$A30)>0,TRUE,FALSE)),"") | R30: =IFERROR(AND(OR(R1:R29,$V30)=TRUE,IF(SEARCH(R$1,$A30)>0,TRUE,FALSE)),"") | S30: =IFERROR(AND(OR(S1:S29,$V30)=TRUE,IF(SEARCH(S$1,$A30)>0,TRUE,FALSE)),"") -> FALSE | T30: =COUNTIF(F30:S30,TRUE) -> 0 | U30: =IFERROR(AND(F30:S30), TRUE) -> FALSE | V30: =IF(E30="Y",TRUE,IF(E30="N",FALSE,0)) -> FALSE | W30: =IF(V30=FALSE, FALSE, U30) -> FALSE | X30: =IF(C30>'Overview (RESPONSES REQUIRED)'!$C$31,FALSE,TRUE) -> FALSE | Y30: =IF(D30>'Overview (RESPONSES REQUIRED)'!$C$34,FALSE,TRUE) -> FALSE | Z30: =AND(X30:Y30) -> FALSE | AA30: =IF(Z30=FALSE,"N",IF(W30=TRUE,"Y",IF(E30=0,"E","N"))) -> N
A31: CA_3C4-7C4-26A2 | B31: 3 | C31: 5 | D31: 18 | E31: =IF('LTE CA'!K33="Y", "Y", IF('LTE CA'!K33="N", "N", 0)) -> N | F31: =IFERROR(AND(OR(F1:G30,$V31)=TRUE,IF(SEARCH(F$1,$A31)>0,TRUE,FALSE)),"") | G31: =IFERROR(AND(OR(G1:G30,$V31)=TRUE,IF(SEARCH(G$1,$A31)>0,TRUE,FALSE)),"") | H31: =IFERROR(AND(OR(H1:K30,$V31)=TRUE,IF(SEARCH(H$1,$A31)>0,TRUE,FALSE)),"") | I31: =IFERROR(AND(OR(I1:K30,$V31)=TRUE,IF(SEARCH(I$1,$A31)>0,TRUE,FALSE)),"") | J31: =IFERROR(AND(OR(J1:K30,$V31)=TRUE,IF(SEARCH(J$1,$A31)>0,TRUE,FALSE)),"") | K31: =IFERROR(AND(OR(K1:K30,$V31)=TRUE,IF(SEARCH(K$1,$A31)>0,TRUE,FALSE)),"") -> FALSE | L31: =IFERROR(AND(OR(L1:L30,$V31)=TRUE,IF(SEARCH(L$1,$A31)>0,TRUE,FALSE)),"") | M31: =IFERROR(AND(OR(M1:P30,$V31)=TRUE,IF(SEARCH(M$1,$A31)>0,TRUE,FALSE)),"") | N31: =IFERROR(AND(OR(N1:P30,$V31)=TRUE,IF(SEARCH(N$1,$A31)>0,TRUE,FALSE)),"") | O31: =IFERROR(AND(OR(O1:P30,$V31)=TRUE,IF(SEARCH(O$1,$A31)>0,TRUE,FALSE)),"") | P31: =IFERROR(AND(OR(P1:P30,$V31)=TRUE,IF(SEARCH(P$1,$A31)>0,TRUE,FALSE)),"") -> FALSE | Q31: =IFERROR(AND(OR(Q1:R30,$V31)=TRUE,IF(SEARCH(Q$1,$A31)>0,TRUE,FALSE)),"") -> FALSE | R31: =IFERROR(AND(OR(R1:R30,$V31)=TRUE,IF(SEARCH(R$1,$A31)>0,TRUE,FALSE)),"") | S31: =IFERROR(AND(OR(S1:S30,$V31)=TRUE,IF(SEARCH(S$1,$A31)>0,TRUE,FALSE)),"") | T31: =COUNTIF(F31:S31,TRUE) -> 0 | U31: =IFERROR(AND(F31:S31), TRUE) -> FALSE | V31: =IF(E31="Y",TRUE,IF(E31="N",FALSE,0)) -> FALSE | W31: =IF(V31=FALSE, FALSE, U31) -> FALSE | X31: =IF(C31>'Overview (RESPONSES REQUIRED)'!$C$31,FALSE,TRUE) -> FALSE | Y31: =IF(D31>'Overview (RESPONSES REQUIRED)'!$C$34,FALSE,TRUE) -> FALSE | Z31: =AND(X31:Y31) -> FALSE | AA31: =IF(Z31=FALSE,"N",IF(W31=TRUE,"Y",IF(E31=0,"E","N"))) -> N
A32: CA_1A2-3C4-7C4 | B32: 3 | C32: 5 | D32: 18 | E32: =IF('LTE CA'!K34="Y", "Y", IF('LTE CA'!K34="N", "N", 0)) -> N | F32: =IFERROR(AND(OR(F1:G31,$V32)=TRUE,IF(SEARCH(F$1,$A32)>0,TRUE,FALSE)),"") -> FALSE | G32: =IFERROR(AND(OR(G1:G31,$V32)=TRUE,IF(SEARCH(G$1,$A32)>0,TRUE,FALSE)),"") | H32: =IFERROR(AND(OR(H1:K31,$V32)=TRUE,IF(SEARCH(H$1,$A32)>0,TRUE,FALSE)),"") | I32: =IFERROR(AND(OR(I1:K31,$V32)=TRUE,IF(SEARCH(I$1,$A32)>0,TRUE,FALSE)),"") | J32: =IFERROR(AND(OR(J1:K31,$V32)=TRUE,IF(SEARCH(J$1,$A32)>0,TRUE,FALSE)),"") | K32: =IFERROR(AND(OR(K1:K31,$V32)=TRUE,IF(SEARCH(K$1,$A32)>0,TRUE,FALSE)),"") -> FALSE | L32: =IFERROR(AND(OR(L1:L31,$V32)=TRUE,IF(SEARCH(L$1,$A32)>0,TRUE,FALSE)),"") | M32: =IFERROR(AND(OR(M1:P31,$V32)=TRUE,IF(SEARCH(M$1,$A32)>0,TRUE,FALSE)),"") | N32: =IFERROR(AND(OR(N1:P31,$V32)=TRUE,IF(SEARCH(N$1,$A32)>0,TRUE,FALSE)),"") | O32: =IFERROR(AND(OR(O1:P31,$V32)=TRUE,IF(SEARCH(O$1,$A32)>0,TRUE,FALSE)),"") | P32: =IFERROR(AND(OR(P1:P31,$V32)=TRUE,IF(SEARCH(P$1,$A32)>0,TRUE,FALSE)),"") -> FALSE | Q32: =IFERROR(AND(OR(Q1:R31,$V32)=TRUE,IF(SEARCH(Q$1,$A32)>0,TRUE,FALSE)),"") | R32: =IFERROR(AND(OR(R1:R31,$V32)=TRUE,IF(SEARCH(R$1,$A32)>0,TRUE,FALSE)),"") | S32: =IFERROR(AND(OR(S1:S31,$V32)=TRUE,IF(SEARCH(S$1,$A32)>0,TRUE,FALSE)),"") | T32: =COUNTIF(F32:S32,TRUE) -> 0 | U32: =IFERROR(AND(F32:S32), TRUE) -> FALSE | V32: =IF(E32="Y",TRUE,IF(E32="N",FALSE,0)) -> FALSE | W32: =IF(V32=FALSE, FALSE, U32) -> FALSE | X32: =IF(C32>'Overview (RESPONSES REQUIRED)'!$C$31,FALSE,TRUE) -> FALSE | Y32: =IF(D32>'Overview (RESPONSES REQUIRED)'!$C$34,FALSE,TRUE) -> FALSE | Z32: =AND(X32:Y32) -> FALSE | AA32: =IF(Z32=FALSE,"N",IF(W32=TRUE,"Y",IF(E32=0,"E","N"))) -> N
A33: CA_1A4-3C2-7C4 | B33: 3 | C33: 5 | D33: 16 | E33: =IF('LTE CA'!K35="Y", "Y", IF('LTE CA'!K35="N", "N", 0)) -> N | F33: =IFERROR(AND(OR(F1:G32,$V33)=TRUE,IF(SEARCH(F$1,$A33)>0,TRUE,FALSE)),"") | G33: =IFERROR(AND(OR(G1:G32,$V33)=TRUE,IF(SEARCH(G$1,$A33)>0,TRUE,FALSE)),"") -> FALSE | H33: =IFERROR(AND(OR(H1:K32,$V33)=TRUE,IF(SEARCH(H$1,$A33)>0,TRUE,FALSE)),"") | I33: =IFERROR(AND(OR(I1:K32,$V33)=TRUE,IF(SEARCH(I$1,$A33)>0,TRUE,FALSE)),"") | J33: =IFERROR(AND(OR(J1:K32,$V33)=TRUE,IF(SEARCH(J$1,$A33)>0,TRUE,FALSE)),"") -> FALSE | K33: =IFERROR(AND(OR(K1:K32,$V33)=TRUE,IF(SEARCH(K$1,$A33)>0,TRUE,FALSE)),"") | L33: =IFERROR(AND(OR(L1:L32,$V33)=TRUE,IF(SEARCH(L$1,$A33)>0,TRUE,FALSE)),"") | M33: =IFERROR(AND(OR(M1:P32,$V33)=TRUE,IF(SEARCH(M$1,$A33)>0,TRUE,FALSE)),"") | N33: =IFERROR(AND(OR(N1:P32,$V33)=TRUE,IF(SEARCH(N$1,$A33)>0,TRUE,FALSE)),"") | O33: =IFERROR(AND(OR(O1:P32,$V33)=TRUE,IF(SEARCH(O$1,$A33)>0,TRUE,FALSE)),"") | P33: =IFERROR(AND(OR(P1:P32,$V33)=TRUE,IF(SEARCH(P$1,$A33)>0,TRUE,FALSE)),"") -> FALSE | Q33: =IFERROR(AND(OR(Q1:R32,$V33)=TRUE,IF(SEARCH(Q$1,$A33)>0,TRUE,FALSE)),"") | R33: =IFERROR(AND(OR(R1:R32,$V33)=TRUE,IF(SEARCH(R$1,$A33)>0,TRUE,FALSE)),"") | S33: =IFERROR(AND(OR(S1:S32,$V33)=TRUE,IF(SEARCH(S$1,$A33)>0,TRUE,FALSE)),"") | T33: =COUNTIF(F33:S33,TRUE) -> 0 | U33: =IFERROR(AND(F33:S33), TRUE) -> FALSE | V33: =IF(E33="Y",TRUE,IF(E33="N",FALSE,0)) -> FALSE | W33: =IF(V33=FALSE, FALSE, U33) -> FALSE | X33: =IF(C33>'Overview (RESPONSES REQUIRED)'!$C$31,FALSE,TRUE) -> FALSE | Y33: =IF(D33>'Overview (RESPONSES REQUIRED)'!$C$34,FALSE,TRUE) -> FALSE | Z33: =AND(X33:Y33) -> FALSE | AA33: =IF(Z33=FALSE,"N",IF(W33=TRUE,"Y",IF(E33=0,"E","N"))) -> N
A34: CA_1A4-3C4-7C2 | B34: 3 | C34: 5 | D34: 16 | E34: =IF('LTE CA'!K36="Y", "Y", IF('LTE CA'!K36="N", "N", 0)) -> N | F34: =IFERROR(AND(OR(F1:G33,$V34)=TRUE,IF(SEARCH(F$1,$A34)>0,TRUE,FALSE)),"") | G34: =IFERROR(AND(OR(G1:G33,$V34)=TRUE,IF(SEARCH(G$1,$A34)>0,TRUE,FALSE)),"") -> FALSE | H34: =IFERROR(AND(OR(H1:K33,$V34)=TRUE,IF(SEARCH(H$1,$A34)>0,TRUE,FALSE)),"") | I34: =IFERROR(AND(OR(I1:K33,$V34)=TRUE,IF(SEARCH(I$1,$A34)>0,TRUE,FALSE)),"") | J34: =IFERROR(AND(OR(J1:K33,$V34)=TRUE,IF(SEARCH(J$1,$A34)>0,TRUE,FALSE)),"") | K34: =IFERROR(AND(OR(K1:K33,$V34)=TRUE,IF(SEARCH(K$1,$A34)>0,TRUE,FALSE)),"") -> FALSE | L34: =IFERROR(AND(OR(L1:L33,$V34)=TRUE,IF(SEARCH(L$1,$A34)>0,TRUE,FALSE)),"") | M34: =IFERROR(AND(OR(M1:P33,$V34)=TRUE,IF(SEARCH(M$1,$A34)>0,TRUE,FALSE)),"") | N34: =IFERROR(AND(OR(N1:P33,$V34)=TRUE,IF(SEARCH(N$1,$A34)>0,TRUE,FALSE)),"") | O34: =IFERROR(AND(OR(O1:P33,$V34)=TRUE,IF(SEARCH(O$1,$A34)>0,TRUE,FALSE)),"") -> FALSE | P34: =IFERROR(AND(OR(P1:P33,$V34)=TRUE,IF(SEARCH(P$1,$A34)>0,TRUE,FALSE)),"") | Q34: =IFERROR(AND(OR(Q1:R33,$V34)=TRUE,IF(SEARCH(Q$1,$A34)>0,TRUE,FALSE)),"") | R34: =IFERROR(AND(OR(R1:R33,$V34)=TRUE,IF(SEARCH(R$1,$A34)>0,TRUE,FALSE)),"") | S34: =IFERROR(AND(OR(S1:S33,$V34)=TRUE,IF(SEARCH(S$1,$A34)>0,TRUE,FALSE)),"") | T34: =COUNTIF(F34:S34,TRUE) -> 0 | U34: =IFERROR(AND(F34:S34), TRUE) -> FALSE | V34: =IF(E34="Y",TRUE,IF(E34="N",FALSE,0)) -> FALSE | W34: =IF(V34=FALSE, FALSE, U34) -> FALSE | X34: =IF(C34>'Overview (RESPONSES REQUIRED)'!$C$31,FALSE,TRUE) -> FALSE | Y34: =IF(D34>'Overview (RESPONSES REQUIRED)'!$C$34,FALSE,TRUE) -> FALSE | Z34: =AND(X34:Y34) -> FALSE | AA34: =IF(Z34=FALSE,"N",IF(W34=TRUE,"Y",IF(E34=0,"E","N"))) -> N
A35: CA_1A4-3A4-7C4 | B35: 3 | C35: 4 | D35: 16 | E35: =IF('LTE CA'!K37="Y", "Y", IF('LTE CA'!K37="N", "N", 0)) -> N | F35: =IFERROR(AND(OR(F1:G34,$V35)=TRUE,IF(SEARCH(F$1,$A35)>0,TRUE,FALSE)),"") | G35: =IFERROR(AND(OR(G1:G34,$V35)=TRUE,IF(SEARCH(G$1,$A35)>0,TRUE,FALSE)),"") -> FALSE | H35: =IFERROR(AND(OR(H1:K34,$V35)=TRUE,IF(SEARCH(H$1,$A35)>0,TRUE,FALSE)),"") | I35: =IFERROR(AND(OR(I1:K34,$V35)=TRUE,IF(SEARCH(I$1,$A35)>0,TRUE,FALSE)),"") -> FALSE | J35: =IFERROR(AND(OR(J1:K34,$V35)=TRUE,IF(SEARCH(J$1,$A35)>0,TRUE,FALSE)),"") | K35: =IFERROR(AND(OR(K1:K34,$V35)=TRUE,IF(SEARCH(K$1,$A35)>0,TRUE,FALSE)),"") | L35: =IFERROR(AND(OR(L1:L34,$V35)=TRUE,IF(SEARCH(L$1,$A35)>0,TRUE,FALSE)),"") | M35: =IFERROR(AND(OR(M1:P34,$V35)=TRUE,IF(SEARCH(M$1,$A35)>0,TRUE,FALSE)),"") | N35: =IFERROR(AND(OR(N1:P34,$V35)=TRUE,IF(SEARCH(N$1,$A35)>0,TRUE,FALSE)),"") | O35: =IFERROR(AND(OR(O1:P34,$V35)=TRUE,IF(SEARCH(O$1,$A35)>0,TRUE,FALSE)),"") | P35: =IFERROR(AND(OR(P1:P34,$V35)=TRUE,IF(SEARCH(P$1,$A35)>0,TRUE,FALSE)),"") -> FALSE | Q35: =IFERROR(AND(OR(Q1:R34,$V35)=TRUE,IF(SEARCH(Q$1,$A35)>0,TRUE,FALSE)),"") | R35: =IFERROR(AND(OR(R1:R34,$V35)=TRUE,IF(SEARCH(R$1,$A35)>0,TRUE,FALSE)),"") | S35: =IFERROR(AND(OR(S1:S34,$V35)=TRUE,IF(SEARCH(S$1,$A35)>0,TRUE,FALSE)),"") | T35: =COUNTIF(F35:S35,TRUE) -> 0 | U35: =IFERROR(AND(F35:S35), TRUE) -> FALSE | V35: =IF(E35="Y",TRUE,IF(E35="N",FALSE,0)) -> FALSE | W35: =IF(V35=FALSE, FALSE, U35) -> FALSE | X35: =IF(C35>'Overview (RESPONSES REQUIRED)'!$C$31,FALSE,TRUE) -> FALSE | Y35: =IF(D35>'Overview (RESPONSES REQUIRED)'!$C$34,FALSE,TRUE) -> FALSE | Z35: =AND(X35:Y35) -> FALSE | AA35: =IF(Z35=FALSE,"N",IF(W35=TRUE,"Y",IF(E35=0,"E","N"))) -> N
A36: CA_1A4-3C4-7A4 | B36: 3 | C36: 4 | D36: 16 | E36: =IF('LTE CA'!K38="Y", "Y", IF('LTE CA'!K38="N", "N", 0)) -> N | F36: =IFERROR(AND(OR(F1:G35,$V36)=TRUE,IF(SEARCH(F$1,$A36)>0,TRUE,FALSE)),"") | G36: =IFERROR(AND(OR(G1:G35,$V36)=TRUE,IF(SEARCH(G$1,$A36)>0,TRUE,FALSE)),"") -> FALSE | H36: =IFERROR(AND(OR(H1:K35,$V36)=TRUE,IF(SEARCH(H$1,$A36)>0,TRUE,FALSE)),"") | I36: =IFERROR(AND(OR(I1:K35,$V36)=TRUE,IF(SEARCH(I$1,$A36)>0,TRUE,FALSE)),"") | J36: =IFERROR(AND(OR(J1:K35,$V36)=TRUE,IF(SEARCH(J$1,$A36)>0,TRUE,FALSE)),"") | K36: =IFERROR(AND(OR(K1:K35,$V36)=TRUE,IF(SEARCH(K$1,$A36)>0,TRUE,FALSE)),"") -> FALSE | L36: =IFERROR(AND(OR(L1:L35,$V36)=TRUE,IF(SEARCH(L$1,$A36)>0,TRUE,FALSE)),"") | M36: =IFERROR(AND(OR(M1:P35,$V36)=TRUE,IF(SEARCH(M$1,$A36)>0,TRUE,FALSE)),"") | N36: =IFERROR(AND(OR(N1:P35,$V36)=TRUE,IF(SEARCH(N$1,$A36)>0,TRUE,FALSE)),"") -> FALSE | O36: =IFERROR(AND(OR(O1:P35,$V36)=TRUE,IF(SEARCH(O$1,$A36)>0,TRUE,FALSE)),"") | P36: =IFERROR(AND(OR(P1:P35,$V36)=TRUE,IF(SEARCH(P$1,$A36)>0,TRUE,FALSE)),"") | Q36: =IFERROR(AND(OR(Q1:R35,$V36)=TRUE,IF(SEARCH(Q$1,$A36)>0,TRUE,FALSE)),"") | R36: =IFERROR(AND(OR(R1:R35,$V36)=TRUE,IF(SEARCH(R$1,$A36)>0,TRUE,FALSE)),"") | S36: =IFERROR(AND(OR(S1:S35,$V36)=TRUE,IF(SEARCH(S$1,$A36)>0,TRUE,FALSE)),"") | T36: =COUNTIF(F36:S36,TRUE) -> 0 | U36: =IFERROR(AND(F36:S36), TRUE) -> FALSE | V36: =IF(E36="Y",TRUE,IF(E36="N",FALSE,0)) -> FALSE | W36: =IF(V36=FALSE, FALSE, U36) -> FALSE | X36: =IF(C36>'Overview (RESPONSES REQUIRED)'!$C$31,FALSE,TRUE) -> FALSE | Y36: =IF(D36>'Overview (RESPONSES REQUIRED)'!$C$34,FALSE,TRUE) -> FALSE | Z36: =AND(X36:Y36) -> FALSE | AA36: =IF(Z36=FALSE,"N",IF(W36=TRUE,"Y",IF(E36=0,"E","N"))) -> N
